Workbook

Sheet JHora
A1: ='[1]Selected Chart'!$A$2 -> Chart | B1: ='[1]Selected Chart'!B2 -> Date | C1: ='[1]Selected Chart'!C2 -> Event
A2: C:\Users\sprabhakara2\Google Drive\charts\Family&Self\Sanjay Prabhakaran | B2: 26133 | C2: Born in CIM Stores
B3: 36723 | C3: Joined SJC/SJVC
A4: Natal Chart | B4: 37926 | C4: Bought Car D16 | AF4: 0
B5: 38779 | C5: Marriage D9 | AF5: 0
A6: Date: July 19, 1971 | B6: 41694 | C6: Bought Car D16 | AF6: 0
A7: Time: 9:13:10 | AF7: 0
A8: Time Zone: 5:30:00 (East of GMT) | AF8: 0
A9: Place: 78 E 05' 05", 10 N 57' 47" | AF9: 0
A10: Karur CIM Store, India | AF10: 0
A11: Altitude: 123.00 meters | AF11: 0
AF12: 0
A13: Lunar Yr-Mo: Virodha-krit - Ashadha | AF13: 0
A14: Tithi: Krishna Dwadasi (Me) (28.19% left) | AF14: 0
A15: Vedic Weekday: Monday (Mo) | AF15: 0
A16: Nakshatra: Rohini (Mo) (2.38% left) | AF16: 0
A17: Yoga: Vriddhi (Me) (9.39% left) | AF17: 0
A18: Karana: Taitula (Me) (56.39% left) | AF18: 0
A19: Hora Lord: Mars (5 min sign: Sg) | AF19: 0
A20: Mahakala Hora: Jupiter (5 min sign: Aq) | AF20: 0
A21: Kaala Lord: Rahu (Mahakala: Rahu) | AF21: 0
AF22: 0
A23: Sunrise: 6:03:17 | AF23: 0
A24: Sunset: 18:44:17 | AF24: 0
A25: Janma Ghatis: 7.9117 | AF25: 0
AF26: 0
A27: Ayanamsa: 23-26-39.19 | AF27: 0
A28: Sidereal Time: 4:40:40 | AF28: 0
AF29: 0
A30: Body Longitude Nakshatra Pada Rasi Navamsa | AF30: 0
AF31: 0
A32: Lagna 16 Le 42' 41.46" PPha 2 Le Vi | AF32: 0
A33: Sun - DK 2 Cn 23' 57.13" Puna 4 Cn Cn | AF33: 0
A34: Moon - BK 23 Ta 00' 57.40" Rohi 4 Ta Cn | AF34: 0
A35: Mars (R) - AK 28 Cp 06' 31.19" Dhan 2 Cp Vi | AF35: 0
A36: Mercury - AmK 27 Cn 07' 47.23" Asre 4 Cn Pi | AF36: 0
A37: Jupiter (R) - GK 3 Sc 11' 49.83" Visa 4 Sc Cn | AF37: 0
A38: Venus - MK 21 Ge 32' 26.17" Puna 1 Ge Ar | AF38: 0
A39: Saturn - PiK 9 Ta 53' 06.76" Krit 4 Ta Pi | AF39: 0
A40: Rahu - PK 21 Cp 58' 02.06" Srav 4 Cp Cn | AF40: 0
...

Sheet Basics
A1: =JHora!A2 -> C:\Users\sprabhakara2\Google Drive\charts\Family&Self\Sanjay Prabhakaran
A2: Date Of Birth | B2: =LEFT(TRIM(MID(JHora!A6,6,100)),FIND(" ",TRIM(MID(JHora!A6,6,100)))) -> July | C2: =REPLACE(RIGHT(TRIM(MID(JHora!A6,6,100)),8),3,1,B2) -> 19July 1971 | E2: =VALUE(C2)+VALUE(RIGHT(JHora!A7,12)) -> 26133.384 | G2: =INT(DoB) -> 26133 | H2: =DoB-INT(DoB) -> 0.38414352 | J2: =ROUNDUP((MINUTE(DoB-B44)+HOUR(DoB-B44)*60)/24,0) -> 8 | K2: =HOUR(DoB-B44)*60 -> 180 | P2: {=SUM(L7:L14)} -> -38
A3: Days In Year | B3: 365.25487 | G3: Days | J3: =TIME(0,24,0) -> 0.016666667
A4: Yellow Cells are Input Cells
A5: After you do Edit;Copy Basic Calculations in Jhora. Goto the JHora Sheet and Paste in 1st row 1st col | W5: 1 | X5: 2 | Y5: 3 | Z5: 4 | AA5: 5
G6: Sphuta Deg | H6: Bhavan Deg | I6: Nakhshatra Ruler | J6: Avastha | K6: Retrograde | L6: Graha Tithi | M6: Tithi Lord | N6: D20Deity | O6: D20Deity | P6: D27Deity | Q6: D27Deity | R6: D27 Position | S6: D150Division | T6: D150Index | U6: D150Names | V6: Avastha | W6: AvashtaInt1 | X6: AvashtaInt2 | Y6: AvashtaInt3 | Z6: AvashtaInt4 | AA6: AvashtaInt5 | AB6: GrahaOrder | AC6: MyValue
A7: =TRIM(LEFT(JHora!A32,FIND(" ",JHora!A32))) -> Lagna | B7: =MID(JHora!A32,FIND("'",JHora!A32)-8,2) -> 16 | C7: =MID(JHora!A32,FIND("'",JHora!A32)-5,2) -> Le | D7: =MID(JHora!A32,FIND("'",JHora!A32)-2,2)+VALUE(MID(JHora!A32,FIND("'",JHora!A32)+2,5))/60 -> 42.691 | E7: =INDEX(NakshatraTbl,INT(G7*0.075)+1,1) -> Purva Phalguni | F7: - | G7: =VLOOKUP(C7,RasiDeg,2,0)+B7+D7/60 -> 136.71152 | H7: =B7+D7/60 -> 16.711517 | I7: =INDEX(NakshatraTbl,INT(G7*0.075)+1,3) -> Venus | K7: =NOT(ISERROR(SEARCH("(R)",JHora!A32))) -> 0 | L7: =ROUNDUP(IF((Moon-G7)<0,-1*(180+(Moon-G7)),Moon-G7)/12,0) -> -9 | N7: =INDEX(D20Deities,ROUNDUP(H7/1.5,0)+MOD(ROUNDUP(G7/30,0)-1,2)*20,1) -> bagalāmukhī | O7: =INDEX(D20Deities,ROUNDUP(H7/1.5,0)+MOD(ROUNDUP(G7/30,0)-1,2)*20,2) -> बगलामुखी | P7: =INDEX(D27Deities,ROUNDUP(H7/30*27,0),1) -> śakrāgni | Q7: =INDEX(D27Deities,ROUNDUP(H7/30*27,0),2) -> शक्राग्नि | R7: =INT(H7/900*360)&" s"&" "&TEXT(MOD(H7/30*360,30)/24,"[HH]:MM:ss") -> 6 s 20:32:18 | S7: =MATCH(H7,D150InequalDegrees) -> 84 | T7: =CHOOSE(ROUNDUP(MOD(G7/30,3),0),S7,150-S7+1,MOD(74+S7,150)+1) -> 67 | U7: =INDEX(D150EnglishNames,T7) -> gadaharā | AB7: 0
A8: =TRIM(LEFT(JHora!A33,FIND(" ",JHora!A33))) -> Sun | B8: =MID(JHora!A33,FIND("'",JHora!A33)-8,2) -> 2 | C8: =MID(JHora!A33,FIND("'",JHora!A33)-5,2) -> Cn | D8: =MID(JHora!A33,FIND("'",JHora!A33)-2,2)+VALUE(MID(JHora!A33,FIND("'",JHora!A33)+2,5))/60 -> 23.952167 | E8: =INDEX(NakshatraTbl,INT(G8*0.075)+1,1) -> Punarvasu | F8: =CHOOSE(RANK(H8,H$8:H$15),"Ak","Amk","Bk","Mk","PiK","PuK","Gk","Dk") -> Dk | G8: =VLOOKUP(C8,RasiDeg,2,0)+B8+D8/60 -> 92.399203 | H8: =B8+D8/60 -> 2.3992028 | I8: =INDEX(NakshatraTbl,INT(G8*0.075)+1,3) -> Jupiter | J8: =MOD(ROUNDUP(G8/13.3333333333,0)*1*ROUNDUP(MOD(G8,30)/3.33333,0)+ROUNDUP(Moon/13.333,0)+ROUNDUP(JanmaGhatika,0)+ROUNDUP(Lagna/30,0)+11,12)+1 -> 12 | K8: =NOT(ISERROR(SEARCH("(R)",JHora!A33))) -> 0 | L8: =ROUNDUP(IF((Moon-G8)<0,-1*(180+(Moon-G8)),Moon-G8)/12,0) -> -12 | M8: =INDEX(Tithi,MOD(ABS(L8),8)) -> Mercury | N8: =INDEX(D20Deities,ROUNDUP(H8/1.5,0)+MOD(ROUNDUP(G8/30,0)-1,2)*20,1) -> medhā | O8: =INDEX(D20Deities,ROUNDUP(H8/1.5,0)+MOD(ROUNDUP(G8/30,0)-1,2)*20,2) -> मेधा | P8: =INDEX(D27Deities,ROUNDUP(H8/30*27,0),1) -> vahni | Q8: =INDEX(D27Deities,ROUNDUP(H8/30*27,0),2) -> वह्नि | R8: =INT(H8/900*360)&" s"&" "&TEXT(MOD(H8/30*360,30)/24,"[HH]:MM:ss") -> 0 s 28:47:26 | S8: =MATCH(H8,D150InequalDegrees) -> 13 | T8: =CHOOSE(ROUNDUP(MOD(G8/30,3),0),S8,150-S8+1,MOD(74+S8,150)+1) -> 13 | U8: =INDEX(D150EnglishNames,T8) -> mañjusvanā | V8: =INDEX(ShayanaadiAvastha,J8) -> Nidraa | W8: =MOD(MOD(($J8*$J8+W$5)+11,12)*INDEX(GrahaShayanadiGunanka,$AB8)+2,3)+1 -> 3 | X8: =MOD(MOD(($J8*$J8+X$5)+11,12)*INDEX(GrahaShayanadiGunanka,$AB8)+2,3)+1 -> 2 | Y8: =MOD(MOD(($J8*$J8+Y$5)+11,12)*INDEX(GrahaShayanadiGunanka,$AB8)+2,3)+1 -> 1 | Z8: =MOD(MOD(($J8*$J8+Z$5)+11,12)*INDEX(GrahaShayanadiGunanka,$AB8)+2,3)+1 -> 3 | AA8: =MOD(MOD(($J8*$J8+AA$5)+11,12)*INDEX(GrahaShayanadiGunanka,$AB8)+2,3)+1 -> 2 | AB8: 1 | AC8: 3 | AD8: If Surya is in Sayan Avastha, the native will incur digestive deficiency, many diseases, stoutness of legs, bilious vitiation, ulcer in the anus and heart strokes;
A9: =TRIM(LEFT(JHora!A34,FIND(" ",JHora!A34))) -> Moon | B9: =MID(JHora!A34,FIND("'",JHora!A34)-8,2) -> 23 | C9: =MID(JHora!A34,FIND("'",JHora!A34)-5,2) -> Ta | D9: =MID(JHora!A34,FIND("'",JHora!A34)-2,2)+VALUE(MID(JHora!A34,FIND("'",JHora!A34)+2,5))/60 -> 0.95666667 | E9: =INDEX(NakshatraTbl,INT(G9*0.075)+1,1) -> Rohini | F9: =CHOOSE(RANK(H9,H$8:H$15),"Ak","Amk","Bk","Mk","PiK","PuK","Gk","Dk") -> Bk | G9: =VLOOKUP(C9,RasiDeg,2,0)+B9+D9/60 -> 53.015944 | H9: =B9+D9/60 -> 23.015944 | I9: =INDEX(NakshatraTbl,INT(G9*0.075)+1,3) -> Moon | J9: =MOD(ROUNDUP(G9/13.3333333333,0)*2*ROUNDUP(MOD(G9,30)/3.33333,0)+ROUNDUP(Moon/13.333,0)+ROUNDUP(JanmaGhatika,0)+ROUNDUP(Lagna/30,0)+11,12)+1 -> 1 | K9: =NOT(ISERROR(SEARCH("(R)",JHora!A34))) -> 0 | N9: =INDEX(D20Deities,ROUNDUP(H9/1.5,0)+MOD(ROUNDUP(G9/30,0)-1,2)*20,1) -> sitā | O9: =INDEX(D20Deities,ROUNDUP(H9/1.5,0)+MOD(ROUNDUP(G9/30,0)-1,2)*20,2) -> सिता | P9: =INDEX(D27Deities,ROUNDUP(H9/30*27,0),1) -> viśve aja | Q9: =INDEX(D27Deities,ROUNDUP(H9/30*27,0),2) -> विश्वे अज | R9: =INT(H9/900*360)&" s"&" "&TEXT(MOD(H9/30*360,30)/24,"[HH]:MM:ss") -> 9 s 06:11:29 | S9: =MATCH(H9,D150InequalDegrees) -> 116 | T9: =CHOOSE(ROUNDUP(MOD(G9/30,3),0),S9,150-S9+1,MOD(74+S9,150)+1) -> 35 | U9: =INDEX(D150EnglishNames,T9) -> kṣamā | V9: =INDEX(ShayanaadiAvastha,J9) -> Sayana | W9: =MOD(MOD(($J9*$J9+W$5)+11,12)*INDEX(GrahaShayanadiGunanka,$AB9)+2,3)+1 -> 2 | X9: =MOD(MOD(($J9*$J9+X$5)+11,12)*INDEX(GrahaShayanadiGunanka,$AB9)+2,3)+1 -> 1 | Y9: =MOD(MOD(($J9*$J9+Y$5)+11,12)*INDEX(GrahaShayanadiGunanka,$AB9)+2,3)+1 -> 3 | Z9: =MOD(MOD(($J9*$J9+Z$5)+11,12)*INDEX(GrahaShayanadiGunanka,$AB9)+2,3)+1 -> 2 | AA9: =MOD(MOD(($J9*$J9+AA$5)+11,12)*INDEX(GrahaShayanadiGunanka,$AB9)+2,3)+1 -> 1 | AB9: 2 | AC9: 1 | AD9: if in Upavesan, will be troubled by diseases, be dull-witted, not endowed with mentionable wealth, will be hard-hearted, will do unworthy acts and will steal others’ wealth;
A10: =TRIM(LEFT(JHora!A35,FIND(" ",JHora!A35))) -> Mars | B10: =MID(JHora!A35,FIND("'",JHora!A35)-8,2) -> 28 | C10: =MID(JHora!A35,FIND("'",JHora!A35)-5,2) -> Cp | D10: =MID(JHora!A35,FIND("'",JHora!A35)-2,2)+VALUE(MID(JHora!A35,FIND("'",JHora!A35)+2,5))/60 -> 6.5198333 | E10: =INDEX(NakshatraTbl,INT(G10*0.075)+1,1) -> Shravan | F10: =CHOOSE(RANK(H10,H$8:H$15),"Ak","Amk","Bk","Mk","PiK","PuK","Gk","Dk") -> Ak | G10: =VLOOKUP(C10,RasiDeg,2,0)+B10+D10/60 -> 298.10866 | H10: =B10+D10/60 -> 28.108664 | I10: =INDEX(NakshatraTbl,INT(G10*0.075)+1,3) -> Moon | J10: =MOD(ROUNDUP(G10/13.3333333333,0)*3*ROUNDUP(MOD(G10,30)/3.33333,0)+ROUNDUP(Moon/13.333,0)+ROUNDUP(JanmaGhatika,0)+ROUNDUP(Lagna/30,0)+11,12)+1 -> 2 | K10: =NOT(ISERROR(SEARCH("(R)",JHora!A35))) -> 1 | L10: =ROUNDUP(IF((Moon-G10)<0,-1*(180+(Moon-G10)),Moon-G10)/12,0) -> 6 | M10: =INDEX(Tithi,MOD(ABS(L10),8)) -> Venus | N10: =INDEX(D20Deities,ROUNDUP(H10/1.5,0)+MOD(ROUNDUP(G10/30,0)-1,2)*20,1) -> maṅgalā | O10: =INDEX(D20Deities,ROUNDUP(H10/1.5,0)+MOD(ROUNDUP(G10/30,0)-1,2)*20,2) -> मङ्गला | P10: =INDEX(D27Deities,ROUNDUP(H10/30*27,0),1) -> ahirbudhnya | Q10: =INDEX(D27Deities,ROUNDUP(H10/30*27,0),2) -> अहिर्बुध्न्य | R10: =INT(H10/900*360)&" s"&" "&TEXT(MOD(H10/30*360,30)/24,"[HH]:MM:ss") -> 11 s 07:18:14 | S10: =MATCH(H10,D150InequalDegrees) -> 141 | T10: =CHOOSE(ROUNDUP(MOD(G10/30,3),0),S10,150-S10+1,MOD(74+S10,150)+1) -> 141 | U10: =INDEX(D150EnglishNames,T10) -> kalaśodbhavā | V10: =INDEX(ShayanaadiAvastha,J10) -> Upavesana | W10: =MOD(MOD(($J10*$J10+W$5)+11,12)*INDEX(GrahaShayanadiGunanka,$AB10)+2,3)+1 -> 2 | X10: =MOD(MOD(($J10*$J10+X$5)+11,12)*INDEX(GrahaShayanadiGunanka,$AB10)+2,3)+1 -> 1 | Y10: =MOD(MOD(($J10*$J10+Y$5)+11,12)*INDEX(GrahaShayanadiGunanka,$AB10)+2,3)+1 -> 3 | Z10: =MOD(MOD(($J10*$J10+Z$5)+11,12)*INDEX(GrahaShayanadiGunanka,$AB10)+2,3)+1 -> 2 | AA10: =MOD(MOD(($J10*$J10+AA$5)+11,12)*INDEX(GrahaShayanadiGunanka,$AB10)+2,3)+1 -> 1 | AB10: 3 | AD10: If Mangal is placed in Lagn and happens to be in Netrapani, there will be penury; if placed in other Bhavas, Netrapani will confer rulership of a city.
A11: =TRIM(LEFT(JHora!A36,FIND(" ",JHora!A36))) -> Mercury | B11: =MID(JHora!A36,FIND("'",JHora!A36)-8,2) -> 27 | C11: =MID(JHora!A36,FIND("'",JHora!A36)-5,2) -> Cn | D11: =MID(JHora!A36,FIND("'",JHora!A36)-2,2)+VALUE(MID(JHora!A36,FIND("'",JHora!A36)+2,5))/60 -> 7.7871667 | E11: =INDEX(NakshatraTbl,INT(G11*0.075)+1,1) -> Ashlesha | F11: =CHOOSE(RANK(H11,H$8:H$15),"Ak","Amk","Bk","Mk","PiK","PuK","Gk","Dk") -> Amk | G11: =VLOOKUP(C11,RasiDeg,2,0)+B11+D11/60 -> 117.12979 | H11: =B11+D11/60 -> 27.129786 | I11: =INDEX(NakshatraTbl,INT(G11*0.075)+1,3) -> Merc | J11: =MOD(ROUNDUP(G11/13.3333333333,0)*4*ROUNDUP(MOD(G11,30)/3.33333,0)+ROUNDUP(Moon/13.333,0)+ROUNDUP(JanmaGhatika,0)+ROUNDUP(Lagna/30,0)+11,12)+1 -> 5 | K11: =NOT(ISERROR(SEARCH("(R)",JHora!A36))) -> 0 | L11: =ROUNDUP(IF((Moon-G11)<0,-1*(180+(Moon-G11)),Moon-G11)/12,0) -> -10 | M11: =INDEX(Tithi,MOD(ABS(L11),8)) -> Moon | N11: =INDEX(D20Deities,ROUNDUP(H11/1.5,0)+MOD(ROUNDUP(G11/30,0)-1,2)*20,1) -> maṅgalā | O11: =INDEX(D20Deities,ROUNDUP(H11/1.5,0)+MOD(ROUNDUP(G11/30,0)-1,2)*20,2) -> मङ्गला | P11: =INDEX(D27Deities,ROUNDUP(H11/30*27,0),1) -> ajapād | Q11: =INDEX(D27Deities,ROUNDUP(H11/30*27,0),2) -> अजपाद् | R11: =INT(H11/900*360)&" s"&" "&TEXT(MOD(H11/30*360,30)/24,"[HH]:MM:ss") -> 10 s 25:33:27 | S11: =MATCH(H11,D150InequalDegrees) -> 136 | T11: =CHOOSE(ROUNDUP(MOD(G11/30,3),0),S11,150-S11+1,MOD(74+S11,150)+1) -> 136 | U11: =INDEX(D150EnglishNames,T11) -> smarā | V11: =INDEX(ShayanaadiAvastha,J11) -> Gamana | W11: =MOD(MOD(($J11*$J11+W$5)+11,12)*INDEX(GrahaShayanadiGunanka,$AB11)+2,3)+1 -> 3 | X11: =MOD(MOD(($J11*$J11+X$5)+11,12)*INDEX(GrahaShayanadiGunanka,$AB11)+2,3)+1 -> 3 | Y11: =MOD(MOD(($J11*$J11+Y$5)+11,12)*INDEX(GrahaShayanadiGunanka,$AB11)+2,3)+1 -> 3 | Z11: =MOD(MOD(($J11*$J11+Z$5)+11,12)*INDEX(GrahaShayanadiGunanka,$AB11)+2,3)+1 -> 3 | AA11: =MOD(MOD(($J11*$J11+AA$5)+11,12)*INDEX(GrahaShayanadiGunanka,$AB11)+2,3)+1 -> 3 | AB11: 4 | AD11: if in Agaman, the same effects, due to his being in Gaman, will fructify; (if in Gaman, will visit the courts of kings on many occasions and Goddess Lakshmi will dwell in his abode)
A12: =TRIM(LEFT(JHora!A37,FIND(" ",JHora!A37))) -> Jupiter | B12: =MID(JHora!A37,FIND("'",JHora!A37)-8,2) -> 3 | C12: =MID(JHora!A37,FIND("'",JHora!A37)-5,2) -> Sc | D12: =MID(JHora!A37,FIND("'",JHora!A37)-2,2)+VALUE(MID(JHora!A37,FIND("'",JHora!A37)+2,5))/60 -> 11.8305 | E12: =INDEX(NakshatraTbl,INT(G12*0.075)+1,1) -> Vishakha | F12: =CHOOSE(RANK(H12,H$8:H$15),"Ak","Amk","Bk","Mk","PiK","PuK","Gk","Dk") -> Gk | G12: =VLOOKUP(C12,RasiDeg,2,0)+B12+D12/60 -> 213.19717 | H12: =B12+D12/60 -> 3.197175 | I12: =INDEX(NakshatraTbl,INT(G12*0.075)+1,3) -> Jupiter | J12: =MOD(ROUNDUP(G12/13.3333333333,0)*5*ROUNDUP(MOD(G12,30)/3.33333,0)+ROUNDUP(Moon/13.333,0)+ROUNDUP(JanmaGhatika,0)+ROUNDUP(Lagna/30,0),12) -> 1 | K12: =NOT(ISERROR(SEARCH("(R)",JHora!A37))) -> 1 | L12: =ROUNDUP(IF((Moon-G12)<0,-1*(180+(Moon-G12)),Moon-G12)/12,0) -> -2 | M12: =INDEX(Tithi,MOD(ABS(L12),8)) -> Moon | N12: =INDEX(D20Deities,ROUNDUP(H12/1.5,0)+MOD(ROUNDUP(G12/30,0)-1,2)*20,1) -> chinnaśīrṣā | O12: =INDEX(D20Deities,ROUNDUP(H12/1.5,0)+MOD(ROUNDUP(G12/30,0)-1,2)*20,2) -> छिन्नशीर्षा | P12: =INDEX(D27Deities,ROUNDUP(H12/30*27,0),1) -> vahni | Q12: =INDEX(D27Deities,ROUNDUP(H12/30*27,0),2) -> वह्नि | R12: =INT(H12/900*360)&" s"&" "&TEXT(MOD(H12/30*360,30)/24,"[HH]:MM:ss") -> 1 s 08:21:58 | S12: =MATCH(H12,D150InequalDegrees) -> 16 | T12: =CHOOSE(ROUNDUP(MOD(G12/30,3),0),S12,150-S12+1,MOD(74+S12,150)+1) -> 135 | U12: =INDEX(D150EnglishNames,T12) -> kadalī | V12: =INDEX(ShayanaadiAvastha,J12) -> Sayana | W12: =MOD(MOD(($J12*$J12+W$5)+11,12)*INDEX(GrahaShayanadiGunanka,$AB12)+2,3)+1 -> 2 | X12: =MOD(MOD(($J12*$J12+X$5)+11,12)*INDEX(GrahaShayanadiGunanka,$AB12)+2,3)+1 -> 1 | Y12: =MOD(MOD(($J12*$J12+Y$5)+11,12)*INDEX(GrahaShayanadiGunanka,$AB12)+2,3)+1 -> 3 | Z12: =MOD(MOD(($J12*$J12+Z$5)+11,12)*INDEX(GrahaShayanadiGunanka,$AB12)+2,3)+1 -> 2 | AA12: =MOD(MOD(($J12*$J12+AA$5)+11,12)*INDEX(GrahaShayanadiGunanka,$AB12)+2,3)+1 -> 1 | AB12: 5 | AD12: if in Upavesan, will be garrulous and very proud, will be troubled by the king and enemies and will have ulcers on the feet shanks, face and hands;
A13: =TRIM(LEFT(JHora!A38,FIND(" ",JHora!A38))) -> Venus | B13: =MID(JHora!A38,FIND("'",JHora!A38)-8,2) -> 21 | C13: =MID(JHora!A38,FIND("'",JHora!A38)-5,2) -> Ge | D13: =MID(JHora!A38,FIND("'",JHora!A38)-2,2)+VALUE(MID(JHora!A38,FIND("'",JHora!A38)+2,5))/60 -> 32.436167 | E13: =INDEX(NakshatraTbl,INT(G13*0.075)+1,1) -> Punarvasu | F13: =CHOOSE(RANK(H13,H$8:H$15),"Ak","Amk","Bk","Mk","PiK","PuK","Gk","Dk") -> Mk | G13: =VLOOKUP(C13,RasiDeg,2,0)+B13+D13/60 -> 81.540603 | H13: =B13+D13/60 -> 21.540603 | I13: =INDEX(NakshatraTbl,INT(G13*0.075)+1,3) -> Jupiter | J13: =MOD(ROUNDUP(G13/13.3333333333,0)*6*ROUNDUP(MOD(G13,30)/3.33333,0)+ROUNDUP(Moon/13.333,0)+ROUNDUP(JanmaGhatika,0)+ROUNDUP(Lagna/30,0)+11,12)+1 -> 11 | K13: =NOT(ISERROR(SEARCH("(R)",JHora!A38))) -> 0 | L13: =ROUNDUP(IF((Moon-G13)<0,-1*(180+(Moon-G13)),Moon-G13)/12,0) -> -13 | M13: =INDEX(Tithi,MOD(ABS(L13),8)) -> Jupiter | N13: =INDEX(D20Deities,ROUNDUP(H13/1.5,0)+MOD(ROUNDUP(G13/30,0)-1,2)*20,1) -> raudrī | O13: =INDEX(D20Deities,ROUNDUP(H13/1.5,0)+MOD(ROUNDUP(G13/30,0)-1,2)*20,2) -> रौद्री | P13: =INDEX(D27Deities,ROUNDUP(H13/30*27,0),1) -> udaka | Q13: =INDEX(D27Deities,ROUNDUP(H13/30*27,0),2) -> उदक | R13: =INT(H13/900*360)&" s"&" "&TEXT(MOD(H13/30*360,30)/24,"[HH]:MM:ss") -> 8 s 18:29:14 | S13: =MATCH(H13,D150InequalDegrees) -> 110 | T13: =CHOOSE(ROUNDUP(MOD(G13/30,3),0),S13,150-S13+1,MOD(74+S13,150)+1) -> 35 | U13: =INDEX(D150EnglishNames,T13) -> kṣamā | V13: =INDEX(ShayanaadiAvastha,J13) -> Kautuka | W13: =MOD(MOD(($J13*$J13+W$5)+11,12)*INDEX(GrahaShayanadiGunanka,$AB13)+2,3)+1 -> 3 | X13: =MOD(MOD(($J13*$J13+X$5)+11,12)*INDEX(GrahaShayanadiGunanka,$AB13)+2,3)+1 -> 3 | Y13: =MOD(MOD(($J13*$J13+Y$5)+11,12)*INDEX(GrahaShayanadiGunanka,$AB13)+2,3)+1 -> 3 | Z13: =MOD(MOD(($J13*$J13+Z$5)+11,12)*INDEX(GrahaShayanadiGunanka,$AB13)+2,3)+1 -> 3 | AA13: =MOD(MOD(($J13*$J13+AA$5)+11,12)*INDEX(GrahaShayanadiGunanka,$AB13)+2,3)+1 -> 3 | AB13: 6 | AD13: if in Nidr, will be interested in serving others, will blame others, be heroic, garrulous and will be wandering all over the earth.
A14: =TRIM(LEFT(JHora!A39,FIND(" ",JHora!A39))) -> Saturn | B14: =MID(JHora!A39,FIND("'",JHora!A39)-8,2) -> 9 | C14: =MID(JHora!A39,FIND("'",JHora!A39)-5,2) -> Ta | D14: =MID(JHora!A39,FIND("'",JHora!A39)-2,2)+VALUE(MID(JHora!A39,FIND("'",JHora!A39)+2,5))/60 -> 53.112667 | E14: =INDEX(NakshatraTbl,INT(G14*0.075)+1,1) -> Kritika | F14: =CHOOSE(RANK(H14,H$8:H$15),"Ak","Amk","Bk","Mk","PiK","PuK","Gk","Dk") -> PiK | G14: =VLOOKUP(C14,RasiDeg,2,0)+B14+D14/60 -> 39.885211 | H14: =B14+D14/60 -> 9.8852111 | I14: =INDEX(NakshatraTbl,INT(G14*0.075)+1,3) -> Sun | J14: =MOD(ROUNDUP(G14/13.3333333333,0)*7*ROUNDUP(MOD(G14,30)/3.33333,0)+ROUNDUP(Moon/13.333,0)+ROUNDUP(JanmaGhatika,0)+ROUNDUP(Lagna/30,0)+11,12)+1 -> 8 | K14: =NOT(ISERROR(SEARCH("(R)",JHora!A39))) -> 0 | L14: =ROUNDUP(IF((Moon-G14)<0,-1*(180+(Moon-G14)),Moon-G14)/12,0) -> 2 | M14: =INDEX(Tithi,MOD(ABS(L14),8)) -> Moon | N14: =INDEX(D20Deities,ROUNDUP(H14/1.5,0)+MOD(ROUNDUP(G14/30,0)-1,2)*20,1) -> bālā | O14: =INDEX(D20Deities,ROUNDUP(H14/1.5,0)+MOD(ROUNDUP(G14/30,0)-1,2)*20,2) -> बाला | P14: =INDEX(D27Deities,ROUNDUP(H14/30*27,0),1) -> ahi | Q14: =INDEX(D27Deities,ROUNDUP(H14/30*27,0),2) -> अहि | R14: =INT(H14/900*360)&" s"&" "&TEXT(MOD(H14/30*360,30)/24,"[HH]:MM:ss") -> 3 s 28:37:21 | S14: =MATCH(H14,D150InequalDegrees) -> 51 | T14: =CHOOSE(ROUNDUP(MOD(G14/30,3),0),S14,150-S14+1,MOD(74+S14,150)+1) -> 100 | U14: =INDEX(D150EnglishNames,T14) -> sārā | V14: =INDEX(ShayanaadiAvastha,J14) -> Aagama | W14: =MOD(MOD(($J14*$J14+W$5)+11,12)*INDEX(GrahaShayanadiGunanka,$AB14)+2,3)+1 -> 3 | X14: =MOD(MOD(($J14*$J14+X$5)+11,12)*INDEX(GrahaShayanadiGunanka,$AB14)+2,3)+1 -> 3 | Y14: =MOD(MOD(($J14*$J14+Y$5)+11,12)*INDEX(GrahaShayanadiGunanka,$AB14)+2,3)+1 -> 3 | Z14: =MOD(MOD(($J14*$J14+Z$5)+11,12)*INDEX(GrahaShayanadiGunanka,$AB14)+2,3)+1 -> 3 | AA14: =MOD(MOD(($J14*$J14+AA$5)+11,12)*INDEX(GrahaShayanadiGunanka,$AB14)+2,3)+1 -> 3 | AB14: 7 | AC14: 3 | AD14: if in Bhojan, will enjoy tastes of food, will be weak-sighted and will be fickle-minded, due to mental delusion;
A15: =TRIM(LEFT(JHora!A40,FIND(" ",JHora!A40))) -> Rahu | B15: =MID(JHora!A40,FIND("'",JHora!A40)-8,2) -> 21 | C15: =MID(JHora!A40,FIND("'",JHora!A40)-5,2) -> Cp | D15: =MID(JHora!A40,FIND("'",JHora!A40)-2,2)+VALUE(MID(JHora!A40,FIND("'",JHora!A40)+2,5))/60 -> 58.034333 | E15: =INDEX(NakshatraTbl,INT(G15*0.075)+1,1) -> Abhijit | F15: =CHOOSE(RANK(H15,H$8:H$15),"Ak","Amk","Bk","Mk","PiK","PuK","Gk","Dk") -> PuK | G15: =VLOOKUP(C15,RasiDeg,2,0)+B15+D15/60 -> 291.96724 | H15: =30-(B15+D15/60) -> 8.0327611 | I15: =INDEX(NakshatraTbl,INT(G15*0.075)+1,3) -> Sun | J15: =MOD(ROUNDUP(G15/13.3333333333,0)*8*ROUNDUP(MOD(G15,30)/3.33333,0)+ROUNDUP(Moon/13.333,0)+ROUNDUP(JanmaGhatika,0)+ROUNDUP(Lagna/30,0)+11,12)+1 -> 1 | K15: =NOT(ISERROR(SEARCH("(R)",JHora!A40))) -> 0 | N15: =INDEX(D20Deities,ROUNDUP(H15/1.5,0)+MOD(ROUNDUP(G15/30,0)-1,2)*20,1) -> mātaṅgī | O15: =INDEX(D20Deities,ROUNDUP(H15/1.5,0)+MOD(ROUNDUP(G15/30,0)-1,2)*20,2) -> मातङ्गी | P15: =INDEX(D27Deities,ROUNDUP(H15/30*27,0),1) -> jīva | Q15: =INDEX(D27Deities,ROUNDUP(H15/30*27,0),2) -> जीव | R15: =INT(H15/900*360)&" s"&" "&TEXT(MOD(H15/30*360,30)/24,"[HH]:MM:ss") -> 3 s 06:23:35 | S15: =MATCH(H15,D150InequalDegrees) -> 40 | T15: =CHOOSE(ROUNDUP(MOD(G15/30,3),0),S15,150-S15+1,MOD(74+S15,150)+1) -> 40 | U15: =INDEX(D150EnglishNames,T15) -> vikaṭā | V15: =INDEX(ShayanaadiAvastha,J15) -> Sayana | W15: =MOD(MOD(($J15*$J15+W$5)+11,12)*INDEX(GrahaShayanadiGunanka,$AB15)+2,3)+1 -> 1 | X15: =MOD(MOD(($J15*$J15+X$5)+11,12)*INDEX(GrahaShayanadiGunanka,$AB15)+2,3)+1 -> 2 | Y15: =MOD(MOD(($J15*$J15+Y$5)+11,12)*INDEX(GrahaShayanadiGunanka,$AB15)+2,3)+1 -> 3 | Z15: =MOD(MOD(($J15*$J15+Z$5)+11,12)*INDEX(GrahaShayanadiGunanka,$AB15)+2,3)+1 -> 1 | AA15: =MOD(MOD(($J15*$J15+AA$5)+11,12)*INDEX(GrahaShayanadiGunanka,$AB15)+2,3)+1 -> 2 | AB15: 8 | AD15: If Rahu is in Upavesan, the native will be distressed, due to ulcers, will be endowed with royal association, be highly honourable and ever devoid of financial happiness;
A16: =TRIM(LEFT(JHora!A41,FIND(" ",JHora!A41))) -> Ketu | B16: =MID(JHora!A41,FIND("'",JHora!A41)-8,2) -> 21 | C16: =MID(JHora!A41,FIND("'",JHora!A41)-5,2) -> Cn | D16: =MID(JHora!A41,FIND("'",JHora!A41)-2,2)+VALUE(MID(JHora!A41,FIND("'",JHora!A41)+2,5))/60 -> 58.034333 | E16: =INDEX(NakshatraTbl,INT(G16*0.075)+1,1) -> Ashlesha | F16: - | G16: =VLOOKUP(C16,RasiDeg,2,0)+B16+D16/60 -> 111.96724 | H16: =B16+D16/60 -> 21.967239 | I16: =INDEX(NakshatraTbl,INT(G16*0.075)+1,3) -> Merc | J16: =MOD(ROUNDUP(G16/13.3333333333,0)*9*ROUNDUP(MOD(G16,30)/3.33333,0)+ROUNDUP(Moon/13.333,0)+ROUNDUP(JanmaGhatika,0)+ROUNDUP(Lagna/30,0)+11,12)+1 -> 8 | K16: =NOT(ISERROR(SEARCH("(R)",JHora!A41))) -> 0 | N16: =INDEX(D20Deities,ROUNDUP(H16/1.5,0)+MOD(ROUNDUP(G16/30,0)-1,2)*20,1) -> vaiṣṇavī | O16: =INDEX(D20Deities,ROUNDUP(H16/1.5,0)+MOD(ROUNDUP(G16/30,0)-1,2)*20,2) -> वैष्णवी | P16: =INDEX(D27Deities,ROUNDUP(H16/30*27,0),1) -> udaka | Q16: =INDEX(D27Deities,ROUNDUP(H16/30*27,0),2) -> उदक | R16: =INT(H16/900*360)&" s"&" "&TEXT(MOD(H16/30*360,30)/24,"[HH]:MM:ss") -> 8 s 23:36:25 | S16: =MATCH(H16,D150InequalDegrees) -> 111 | T16: =CHOOSE(ROUNDUP(MOD(G16/30,3),0),S16,150-S16+1,MOD(74+S16,150)+1) -> 111 | U16: =INDEX(D150EnglishNames,T16) -> brahmiḥ | V16: =INDEX(ShayanaadiAvastha,J16) -> Aagama | W16: =MOD(MOD(($J16*$J16+W$5)+11,12)*INDEX(GrahaShayanadiGunanka,$AB16)+2,3)+1 -> 1 | X16: =MOD(MOD(($J16*$J16+X$5)+11,12)*INDEX(GrahaShayanadiGunanka,$AB16)+2,3)+1 -> 2 | Y16: =MOD(MOD(($J16*$J16+Y$5)+11,12)*INDEX(GrahaShayanadiGunanka,$AB16)+2,3)+1 -> 3 | Z16: =MOD(MOD(($J16*$J16+Z$5)+11,12)*INDEX(GrahaShayanadiGunanka,$AB16)+2,3)+1 -> 1 | AA16: =MOD(MOD(($J16*$J16+AA$5)+11,12)*INDEX(GrahaShayanadiGunanka,$AB16)+2,3)+1 -> 2 | AB16: 9 | AD16: if in Bhojan, will always be distressed with hunger, penury and diseases and will roam all over the earth;
A17: =TRIM(LEFT(JHora!A42,FIND(" ",JHora!A42))) -> Maandi | B17: =MID(JHora!A42,FIND("'",JHora!A42)-8,2) -> 8 | C17: =MID(JHora!A42,FIND("'",JHora!A42)-5,2) -> Sc | D17: =MID(JHora!A42,FIND("'",JHora!A42)-2,2)+VALUE(MID(JHora!A42,FIND("'",JHora!A42)+2,5))/60 -> 13.930167 | E17: =INDEX(NakshatraTbl,INT(G17*0.075)+1,1) -> Anuradha | F17: - | G17: =VLOOKUP(C17,RasiDeg,2,0)+B17+D17/60 -> 218.23217 | H17: =B17+D17/60 -> 8.2321694 | I17: =INDEX(NakshatraTbl,INT(G17*0.075)+1,3) -> Sat | N17: =INDEX(D20Deities,ROUNDUP(H17/1.5,0)+MOD(ROUNDUP(G17/30,0)-1,2)*20,1) -> mātaṅgī | O17: =INDEX(D20Deities,ROUNDUP(H17/1.5,0)+MOD(ROUNDUP(G17/30,0)-1,2)*20,2) -> मातङ्गी | P17: =INDEX(D27Deities,ROUNDUP(H17/30*27,0),1) -> jīva | Q17: =INDEX(D27Deities,ROUNDUP(H17/30*27,0),2) -> जीव | R17: =INT(H17/900*360)&" s"&" "&TEXT(MOD(H17/30*360,30)/24,"[HH]:MM:ss") -> 3 s 08:47:10 | S17: =MATCH(H17,D150InequalDegrees) -> 40 | T17: =CHOOSE(ROUNDUP(MOD(G17/30,3),0),S17,150-S17+1,MOD(74+S17,150)+1) -> 111 | U17: =INDEX(D150EnglishNames,T17) -> brahmiḥ
A18: =TRIM(LEFT(JHora!A43,FIND(" ",JHora!A43))) -> Gulika | B18: =MID(JHora!A43,FIND("'",JHora!A43)-8,2) -> 19 | C18: =MID(JHora!A43,FIND("'",JHora!A43)-5,2) -> Sc | D18: =MID(JHora!A43,FIND("'",JHora!A43)-2,2)+VALUE(MID(JHora!A43,FIND("'",JHora!A43)+2,5))/60 -> 6.2461667 | E18: =INDEX(NakshatraTbl,INT(G18*0.075)+1,1) -> Jyeshtha | F18: - | G18: =VLOOKUP(C18,RasiDeg,2,0)+B18+D18/60 -> 229.1041 | H18: =B18+D18/60 -> 19.104103 | I18: =INDEX(NakshatraTbl,INT(G18*0.075)+1,3) -> Merc | N18: =INDEX(D20Deities,ROUNDUP(H18/1.5,0)+MOD(ROUNDUP(G18/30,0)-1,2)*20,1) -> ghorā | O18: =INDEX(D20Deities,ROUNDUP(H18/1.5,0)+MOD(ROUNDUP(G18/30,0)-1,2)*20,2) -> घोरा | P18: =INDEX(D27Deities,ROUNDUP(H18/30*27,0),1) -> vāsava | Q18: =INDEX(D27Deities,ROUNDUP(H18/30*27,0),2) -> वासव | R18: =INT(H18/900*360)&" s"&" "&TEXT(MOD(H18/30*360,30)/24,"[HH]:MM:ss") -> 7 s 19:14:57 | S18: =MATCH(H18,D150InequalDegrees) -> 97 | T18: =CHOOSE(ROUNDUP(MOD(G18/30,3),0),S18,150-S18+1,MOD(74+S18,150)+1) -> 54 | U18: =INDEX(D150EnglishNames,T18) -> viṣākhyā
A19: =TRIM(LEFT(JHora!A44,FIND(" ",JHora!A44))) -> Bhava | B19: =MID(JHora!A44,FIND("'",JHora!A44)-8,2) -> 19 | C19: =MID(JHora!A44,FIND("'",JHora!A44)-5,2) -> Le | D19: =MID(JHora!A44,FIND("'",JHora!A44)-2,2)+VALUE(MID(JHora!A44,FIND("'",JHora!A44)+2,5))/60 -> 52.181667 | E19: =INDEX(NakshatraTbl,INT(G19*0.075)+1,1) -> Purva Phalguni | F19: - | G19: =VLOOKUP(C19,RasiDeg,2,0)+B19+D19/60 -> 139.86969 | H19: =B19+D19/60 -> 19.869694 | I19: =INDEX(NakshatraTbl,INT(G19*0.075)+1,3) -> Venus | N19: =INDEX(D20Deities,ROUNDUP(H19/1.5,0)+MOD(ROUNDUP(G19/30,0)-1,2)*20,1) -> śacī | O19: =INDEX(D20Deities,ROUNDUP(H19/1.5,0)+MOD(ROUNDUP(G19/30,0)-1,2)*20,2) -> शची | P19: =INDEX(D27Deities,ROUNDUP(H19/30*27,0),1) -> vāsava | Q19: =INDEX(D27Deities,ROUNDUP(H19/30*27,0),2) -> वासव | R19: =INT(H19/900*360)&" s"&" "&TEXT(MOD(H19/30*360,30)/24,"[HH]:MM:ss") -> 7 s 28:26:11 | S19: =MATCH(H19,D150InequalDegrees) -> 99 | T19: =CHOOSE(ROUNDUP(MOD(G19/30,3),0),S19,150-S19+1,MOD(74+S19,150)+1) -> 52 | U19: =INDEX(D150EnglishNames,T19) -> kundinī
A20: =TRIM(LEFT(JHora!A45,FIND(" ",JHora!A45))) -> Hora | B20: =MID(JHora!A45,FIND("'",JHora!A45)-8,2) -> 7 | C20: =MID(JHora!A45,FIND("'",JHora!A45)-5,2) -> Li | D20: =MID(JHora!A45,FIND("'",JHora!A45)-2,2)+VALUE(MID(JHora!A45,FIND("'",JHora!A45)+2,5))/60 -> 20.411333 | E20: =INDEX(NakshatraTbl,INT(G20*0.075)+1,1) -> Swati | F20: - | G20: =VLOOKUP(C20,RasiDeg,2,0)+B20+D20/60 -> 187.34019 | H20: =B20+D20/60 -> 7.3401889 | I20: =INDEX(NakshatraTbl,INT(G20*0.075)+1,3) -> Rahu | N20: =INDEX(D20Deities,ROUNDUP(H20/1.5,0)+MOD(ROUNDUP(G20/30,0)-1,2)*20,1) -> vijayā | O20: =INDEX(D20Deities,ROUNDUP(H20/1.5,0)+MOD(ROUNDUP(G20/30,0)-1,2)*20,2) -> विजया | P20: =INDEX(D27Deities,ROUNDUP(H20/30*27,0),1) -> aditi | Q20: =INDEX(D27Deities,ROUNDUP(H20/30*27,0),2) -> अदिति | R20: =INT(H20/900*360)&" s"&" "&TEXT(MOD(H20/30*360,30)/24,"[HH]:MM:ss") -> 2 s 28:04:56 | S20: =MATCH(H20,D150InequalDegrees) -> 37 | T20: =CHOOSE(ROUNDUP(MOD(G20/30,3),0),S20,150-S20+1,MOD(74+S20,150)+1) -> 37 | U20: =INDEX(D150EnglishNames,T20) -> durbhagā
A21: =TRIM(LEFT(JHora!A46,FIND(" ",JHora!A46))) -> Ghati | B21: =MID(JHora!A46,FIND("'",JHora!A46)-8,2) -> 29 | C21: =MID(JHora!A46,FIND("'",JHora!A46)-5,2) -> Aq | D21: =MID(JHora!A46,FIND("'",JHora!A46)-2,2)+VALUE(MID(JHora!A46,FIND("'",JHora!A46)+2,5))/60 -> 45.099833 | E21: =INDEX(NakshatraTbl,INT(G21*0.075)+1,1) -> Satabishak | F21: - | G21: =VLOOKUP(C21,RasiDeg,2,0)+B21+D21/60 -> 329.75166 | H21: =B21+D21/60 -> 29.751664 | I21: =INDEX(NakshatraTbl,INT(G21*0.075)+1,3) -> Rahu | N21: =INDEX(D20Deities,ROUNDUP(H21/1.5,0)+MOD(ROUNDUP(G21/30,0)-1,2)*20,1) -> sumukhī | O21: =INDEX(D20Deities,ROUNDUP(H21/1.5,0)+MOD(ROUNDUP(G21/30,0)-1,2)*20,2) -> सुमुखी | P21: =INDEX(D27Deities,ROUNDUP(H21/30*27,0),1) -> pūṣā | Q21: =INDEX(D27Deities,ROUNDUP(H21/30*27,0),2) -> पूषा | R21: =INT(H21/900*360)&" s"&" "&TEXT(MOD(H21/30*360,30)/24,"[HH]:MM:ss") -> 11 s 27:01:12 | S21: =MATCH(H21,D150InequalDegrees) -> 150 | T21: =CHOOSE(ROUNDUP(MOD(G21/30,3),0),S21,150-S21+1,MOD(74+S21,150)+1) -> 1 | U21: =INDEX(D150EnglishNames,T21) -> vasudhā
A22: =TRIM(LEFT(JHora!A47,FIND(" ",JHora!A47))) -> Vighati | B22: =MID(JHora!A47,FIND("'",JHora!A47)-8,2) -> 21 | C22: =MID(JHora!A47,FIND("'",JHora!A47)-5,2) -> Aq | D22: =MID(JHora!A47,FIND("'",JHora!A47)-2,2)+VALUE(MID(JHora!A47,FIND("'",JHora!A47)+2,5))/60 -> 48.543 | E22: =INDEX(NakshatraTbl,INT(G22*0.075)+1,1) -> Satabishak | F22: - | G22: =VLOOKUP(C22,RasiDeg,2,0)+B22+D22/60 -> 321.80905 | H22: =B22+D22/60 -> 21.80905 | I22: =INDEX(NakshatraTbl,INT(G22*0.075)+1,3) -> Rahu | N22: =INDEX(D20Deities,ROUNDUP(H22/1.5,0)+MOD(ROUNDUP(G22/30,0)-1,2)*20,1) -> raudrī | O22: =INDEX(D20Deities,ROUNDUP(H22/1.5,0)+MOD(ROUNDUP(G22/30,0)-1,2)*20,2) -> रौद्री | P22: =INDEX(D27Deities,ROUNDUP(H22/30*27,0),1) -> udaka | Q22: =INDEX(D27Deities,ROUNDUP(H22/30*27,0),2) -> उदक | R22: =INT(H22/900*360)&" s"&" "&TEXT(MOD(H22/30*360,30)/24,"[HH]:MM:ss") -> 8 s 21:42:31 | S22: =MATCH(H22,D150InequalDegrees) -> 111 | T22: =CHOOSE(ROUNDUP(MOD(G22/30,3),0),S22,150-S22+1,MOD(74+S22,150)+1) -> 40 | U22: =INDEX(D150EnglishNames,T22) -> vikaṭā
A23: =TRIM(LEFT(JHora!A48,FIND(" ",JHora!A48))) -> Varnada | B23: =MID(JHora!A48,FIND("'",JHora!A48)-8,2) -> 16 | C23: =MID(JHora!A48,FIND("'",JHora!A48)-5,2) -> Pi | D23: =MID(JHora!A48,FIND("'",JHora!A48)-2,2)+VALUE(MID(JHora!A48,FIND("'",JHora!A48)+2,5))/60 -> 42.691 | E23: =INDEX(NakshatraTbl,INT(G23*0.075)+1,1) -> Uttara Bhadrapad | F23: - | G23: =VLOOKUP(C23,RasiDeg,2,0)+B23+D23/60 -> 346.71152 | H23: =B23+D23/60 -> 16.711517 | I23: =INDEX(NakshatraTbl,INT(G23*0.075)+1,3) -> Sat | N23: =INDEX(D20Deities,ROUNDUP(H23/1.5,0)+MOD(ROUNDUP(G23/30,0)-1,2)*20,1) -> chucchukā | O23: =INDEX(D20Deities,ROUNDUP(H23/1.5,0)+MOD(ROUNDUP(G23/30,0)-1,2)*20,2) -> छुच्छुका | P23: =INDEX(D27Deities,ROUNDUP(H23/30*27,0),1) -> śakrāgni | Q23: =INDEX(D27Deities,ROUNDUP(H23/30*27,0),2) -> शक्राग्नि | R23: =INT(H23/900*360)&" s"&" "&TEXT(MOD(H23/30*360,30)/24,"[HH]:MM:ss") -> 6 s 20:32:18 | S23: =MATCH(H23,D150InequalDegrees) -> 84 | T23: =CHOOSE(ROUNDUP(MOD(G23/30,3),0),S23,150-S23+1,MOD(74+S23,150)+1) -> 9 | U23: =INDEX(D150EnglishNames,T23) -> surā
A24: =TRIM(LEFT(JHora!A49,FIND(" ",JHora!A49))) -> Sree | B24: =MID(JHora!A49,FIND("'",JHora!A49)-8,2) -> 8 | C24: =MID(JHora!A49,FIND("'",JHora!A49)-5,2) -> Le | D24: =MID(JHora!A49,FIND("'",JHora!A49)-2,2)+VALUE(MID(JHora!A49,FIND("'",JHora!A49)+2,5))/60 -> 8.519 | E24: =INDEX(NakshatraTbl,INT(G24*0.075)+1,1) -> Magha | F24: - | G24: =VLOOKUP(C24,RasiDeg,2,0)+B24+D24/60 -> 128.14198 | H24: =B24+D24/60 -> 8.1419833 | I24: =INDEX(NakshatraTbl,INT(G24*0.075)+1,3) -> Ketu | N24: =INDEX(D20Deities,ROUNDUP(H24/1.5,0)+MOD(ROUNDUP(G24/30,0)-1,2)*20,1) -> vimalā | O24: =INDEX(D20Deities,ROUNDUP(H24/1.5,0)+MOD(ROUNDUP(G24/30,0)-1,2)*20,2) -> विमला | P24: =INDEX(D27Deities,ROUNDUP(H24/30*27,0),1) -> jīva | Q24: =INDEX(D27Deities,ROUNDUP(H24/30*27,0),2) -> जीव | R24: =INT(H24/900*360)&" s"&" "&TEXT(MOD(H24/30*360,30)/24,"[HH]:MM:ss") -> 3 s 07:42:14 | S24: =MATCH(H24,D150InequalDegrees) -> 40 | T24: =CHOOSE(ROUNDUP(MOD(G24/30,3),0),S24,150-S24+1,MOD(74+S24,150)+1) -> 111 | U24: =INDEX(D150EnglishNames,T24) -> brahmiḥ
A25: =TRIM(LEFT(JHora!A50,FIND(" ",JHora!A50))) -> Pranapada | B25: =MID(JHora!A50,FIND("'",JHora!A50)-8,2) -> 21 | C25: =MID(JHora!A50,FIND("'",JHora!A50)-5,2) -> Aq | D25: =MID(JHora!A50,FIND("'",JHora!A50)-2,2)+VALUE(MID(JHora!A50,FIND("'",JHora!A50)+2,5))/60 -> 48.543 | E25: =INDEX(NakshatraTbl,INT(G25*0.075)+1,1) -> Satabishak | F25: - | G25: =VLOOKUP(C25,RasiDeg,2,0)+B25+D25/60 -> 321.80905 | H25: =B25+D25/60 -> 21.80905 | I25: =INDEX(NakshatraTbl,INT(G25*0.075)+1,3) -> Rahu | N25: =INDEX(D20Deities,ROUNDUP(H25/1.5,0)+MOD(ROUNDUP(G25/30,0)-1,2)*20,1) -> raudrī | O25: =INDEX(D20Deities,ROUNDUP(H25/1.5,0)+MOD(ROUNDUP(G25/30,0)-1,2)*20,2) -> रौद्री | P25: =INDEX(D27Deities,ROUNDUP(H25/30*27,0),1) -> udaka | Q25: =INDEX(D27Deities,ROUNDUP(H25/30*27,0),2) -> उदक | R25: =INT(H25/900*360)&" s"&" "&TEXT(MOD(H25/30*360,30)/24,"[HH]:MM:ss") -> 8 s 21:42:31 | S25: =MATCH(H25,D150InequalDegrees) -> 111 | T25: =CHOOSE(ROUNDUP(MOD(G25/30,3),0),S25,150-S25+1,MOD(74+S25,150)+1) -> 40 | U25: =INDEX(D150EnglishNames,T25) -> vikaṭā
A26: =TRIM(LEFT(JHora!A51,FIND(" ",JHora!A51))) -> Indu | B26: =MID(JHora!A51,FIND("'",JHora!A51)-8,2) -> 23 | C26: =MID(JHora!A51,FIND("'",JHora!A51)-5,2) -> Sc | D26: =MID(JHora!A51,FIND("'",JHora!A51)-2,2)+VALUE(MID(JHora!A51,FIND("'",JHora!A51)+2,5))/60 -> 0.95666667 | E26: =INDEX(NakshatraTbl,INT(G26*0.075)+1,1) -> Jyeshtha | F26: - | G26: =VLOOKUP(C26,RasiDeg,2,0)+B26+D26/60 -> 233.01594 | H26: =B26+D26/60 -> 23.015944 | I26: =INDEX(NakshatraTbl,INT(G26*0.075)+1,3) -> Merc | N26: =INDEX(D20Deities,ROUNDUP(H26/1.5,0)+MOD(ROUNDUP(G26/30,0)-1,2)*20,1) -> sitā | O26: =INDEX(D20Deities,ROUNDUP(H26/1.5,0)+MOD(ROUNDUP(G26/30,0)-1,2)*20,2) -> सिता | P26: =INDEX(D27Deities,ROUNDUP(H26/30*27,0),1) -> viśve aja | Q26: =INDEX(D27Deities,ROUNDUP(H26/30*27,0),2) -> विश्वे अज | R26: =INT(H26/900*360)&" s"&" "&TEXT(MOD(H26/30*360,30)/24,"[HH]:MM:ss") -> 9 s 06:11:29 | S26: =MATCH(H26,D150InequalDegrees) -> 116 | T26: =CHOOSE(ROUNDUP(MOD(G26/30,3),0),S26,150-S26+1,MOD(74+S26,150)+1) -> 35 | U26: =INDEX(D150EnglishNames,T26) -> kṣamā
A27: =TRIM(LEFT(JHora!A52,FIND(" ",JHora!A52))) -> Bhrigu | B27: =MID(JHora!A52,FIND("'",JHora!A52)-8,2) -> 22 | C27: =MID(JHora!A52,FIND("'",JHora!A52)-5,2) -> Pi | D27: =MID(JHora!A52,FIND("'",JHora!A52)-2,2)+VALUE(MID(JHora!A52,FIND("'",JHora!A52)+2,5))/60 -> 29.4955 | E27: =INDEX(NakshatraTbl,INT(G27*0.075)+1,1) -> Uttara Bhadrapad | F27: - | G27: =VLOOKUP(C27,RasiDeg,2,0)+B27+D27/60 -> 352.49159 | H27: =B27+D27/60 -> 22.491592 | I27: =INDEX(NakshatraTbl,INT(G27*0.075)+1,3) -> Sat | N27: =INDEX(D20Deities,ROUNDUP(H27/1.5,0)+MOD(ROUNDUP(G27/30,0)-1,2)*20,1) -> vaiṣṇavī | O27: =INDEX(D20Deities,ROUNDUP(H27/1.5,0)+MOD(ROUNDUP(G27/30,0)-1,2)*20,2) -> वैष्णवी | P27: =INDEX(D27Deities,ROUNDUP(H27/30*27,0),1) -> viśve aja | Q27: =INDEX(D27Deities,ROUNDUP(H27/30*27,0),2) -> विश्वे अज | R27: =INT(H27/900*360)&" s"&" "&TEXT(MOD(H27/30*360,30)/24,"[HH]:MM:ss") -> 8 s 29:53:57 | S27: =MATCH(H27,D150InequalDegrees) -> 113 | T27: =CHOOSE(ROUNDUP(MOD(G27/30,3),0),S27,150-S27+1,MOD(74+S27,150)+1) -> 38 | U27: =INDEX(D150EnglishNames,T27) -> viśvā
A28: =TRIM(LEFT(JHora!A53,FIND(" ",JHora!A53))) -> Dhooma | B28: =MID(JHora!A53,FIND("'",JHora!A53)-8,2) -> 15 | C28: =MID(JHora!A53,FIND("'",JHora!A53)-5,2) -> Sc | D28: =MID(JHora!A53,FIND("'",JHora!A53)-2,2)+VALUE(MID(JHora!A53,FIND("'",JHora!A53)+2,5))/60 -> 43.952167 | E28: =INDEX(NakshatraTbl,INT(G28*0.075)+1,1) -> Anuradha | F28: - | G28: =VLOOKUP(C28,RasiDeg,2,0)+B28+D28/60 -> 225.73254 | H28: =B28+D28/60 -> 15.732536 | I28: =INDEX(NakshatraTbl,INT(G28*0.075)+1,3) -> Sat | N28: =INDEX(D20Deities,ROUNDUP(H28/1.5,0)+MOD(ROUNDUP(G28/30,0)-1,2)*20,1) -> piṅgalā | O28: =INDEX(D20Deities,ROUNDUP(H28/1.5,0)+MOD(ROUNDUP(G28/30,0)-1,2)*20,2) -> पिङ्गला | P28: =INDEX(D27Deities,ROUNDUP(H28/30*27,0),1) -> maruta | Q28: =INDEX(D27Deities,ROUNDUP(H28/30*27,0),2) -> मरुत | R28: =INT(H28/900*360)&" s"&" "&TEXT(MOD(H28/30*360,30)/24,"[HH]:MM:ss") -> 6 s 08:47:26 | S28: =MATCH(H28,D150InequalDegrees) -> 79 | T28: =CHOOSE(ROUNDUP(MOD(G28/30,3),0),S28,150-S28+1,MOD(74+S28,150)+1) -> 72 | U28: =INDEX(D150EnglishNames,T28) -> sudhāmṛtāṁśuḥ
... A30: =TRIM(LEFT(JHora!A55,FIND(" ",JHora!A55))) -> Parivesha | B30: =MID(JHora!A55,FIND("'",JHora!A55)-8,2) -> 14 | C30: =MID(JHora!A55,FIND("'",JHora!A55)-5,2) -> Aq | D30: =MID(JHora!A55,FIND("'",JHora!A55)-2,2)+VALUE(MID(JHora!A55,FIND("'",JHora!A55)+2,5))/60 -> 16.047833 | E30: =INDEX(NakshatraTbl,INT(G30*0.075)+1,1) -> Dhanistha | F30: - | G30: =VLOOKUP(C30,RasiDeg,2,0)+B30+D30/60 -> 314.26746 | H30: =B30+D30/60 -> 14.267464 | I30: =INDEX(NakshatraTbl,INT(G30*0.075)+1,3) -> Mars | N30: =INDEX(D20Deities,ROUNDUP(H30/1.5,0)+MOD(ROUNDUP(G30/30,0)-1,2)*20,1) -> śvetā | O30: =INDEX(D20Deities,ROUNDUP(H30/1.5,0)+MOD(ROUNDUP(G30/30,0)-1,2)*20,2) -> श्वेता | P30: =INDEX(D27Deities,ROUNDUP(H30/30*27,0),1) -> arka | Q30: =INDEX(D27Deities,ROUNDUP(H30/30*27,0),2) -> अर्क | R30: =INT(H30/900*360)&" s"&" "&TEXT(MOD(H30/30*360,30)/24,"[HH]:MM:ss") -> 5 s 21:12:34 | S30: =MATCH(H30,D150InequalDegrees) -> 72 | T30: =CHOOSE(ROUNDUP(MOD(G30/30,3),0),S30,150-S30+1,MOD(74+S30,150)+1) -> 79 | U30: =INDEX(D150EnglishNames,T30) -> śobhā
A31: Shri Lagna | B31: =FLOOR(MOD(G31,30),1) -> 8 | C31: =INDEX(RasiDeg,ROUNDUP(G31/30,0),1) -> Le | D31: =ROUND((MOD(G31,30)-B31)*60,1) -> 8.5 | E31: =INDEX(NakshatraTbl,INT(G31*0.075)+1,1) -> Magha | G31: =MOD(((MOD(G9,StarDeg)/StarDeg)*360)+G7,360) -> 128.14202 | H31: =B31+D31/60 -> 8.1416667 | I31: =INDEX(NakshatraTbl,INT(G31*0.075)+1,3) -> Ketu
A32: Varnada Lagna | B32: =FLOOR(MOD(G32,30),1) -> 24 | C32: =INDEX(RasiDeg,ROUNDUP(G32/30,0),1) -> Pi | D32: =ROUND((MOD(G32,30)-B32)*60,1) -> 11.1 | E32: =INDEX(NakshatraTbl,INT(G32*0.075)+1,1) -> Uttara Bhadrapad | G32: =MOD(IF(MOD(INT(G7/30)+INT(G18/30),2)=1,(MOD(INT(G7/30),2)*360-G7)+(MOD(INT(G18/30),2)*360-G18),G7+G18),360) -> 354.18438 | H32: =B32+D32/60 -> 24.185 | I32: =INDEX(NakshatraTbl,INT(G32*0.075)+1,3) -> Sat
A33: Varnada Lagna | B33: =FLOOR(MOD(G33,30),1) -> 24 | C33: =INDEX(RasiDeg,ROUNDUP(G33/30,0),1) -> Aq | D33: =ROUND((MOD(G33,30)-B33)*60,1) -> 3.1 | E33: =INDEX(NakshatraTbl,INT(G33*0.075)+1,1) -> Satabishak | G33: =M33 -> 324.05171 | H33: =B33+D33/60 -> 24.051667 | I33: =INDEX(NakshatraTbl,INT(G33*0.075)+1,3) -> Rahu | J33: =IF(MOD(INT(Lagna/30),2),360-Lagna,Lagna) -> 136.71152 | K33: =IF(MOD(INT(HoraLagna/30),2),360-HoraLagna,HoraLagna) -> 187.34019 | L33: =MOD(IF(MOD(INT(J33/30)+INT(K33/30),2),ABS(J33-K33),J33+K33),360) -> 324.05171 | M33: =IF(MOD(INT(L33/30),2),360-L33,L33) -> 324.05171
A34: Utpanna(5th) Star | B34: =FLOOR(MOD(G34,30),1) -> 16 | C34: =INDEX(RasiDeg,ROUNDUP(G34/30,0),1) -> Cn | D34: =ROUND((MOD(G34,30)-B34)*60,1) -> 21 | E34: =INDEX(NakshatraTbl,INT(G34*0.075)+1,1) -> Pushya | G34: =MOD(MoonDeg+4*StarDeg,360) -> 106.34928 | H34: =B34+D34/60 -> 16.35 | I34: =INDEX(NakshatraTbl,INT(G34*0.075)+1,3) -> Sat
A35: Kshema(4th) Star | B35: =FLOOR(MOD(G35,30),1) -> 3 | C35: =INDEX(RasiDeg,ROUNDUP(G35/30,0),1) -> Cn | D35: =ROUND((MOD(G35,30)-B35)*60,1) -> 1 | E35: =INDEX(NakshatraTbl,INT(G35*0.075)+1,1) -> Punarvasu | G35: =MOD(MoonDeg+3*StarDeg,360) -> 93.015944 | H35: =B35+D35/60 -> 3.0166667 | I35: =INDEX(NakshatraTbl,INT(G35*0.075)+1,3) -> Jupiter | K35: =
A36: Sun+Moon | B36: =FLOOR(MOD(G36,30),1) -> 25 | C36: =INDEX(RasiDeg,ROUNDUP(G36/30,0),1) -> Le | D36: =ROUND((MOD(G36,30)-B36)*60,1) -> 24.9 | E36: =INDEX(NakshatraTbl,INT(G36*0.075)+1,1) -> Purva Phalguni | F36: =INDEX(PanchangaYoga,INT((MOD(360+G36,360))*0.075)+1,2) -> Vriddhi | G36: =MOD(SunDeg+MoonDeg,360) -> 145.41515 | H36: =B36+D36/60 -> 25.415 | I36: =INDEX(NakshatraTbl,INT(G36*0.075)+1,3) -> Venus
A37: Panchanga Yoga | B37: =FLOOR(MOD(G37,30),1) -> 28 | C37: =INDEX(RasiDeg,ROUNDUP(G37/30,0),1) -> Sc | D37: =ROUND((MOD(G37,30)-B37)*60,1) -> 44.9 | E37: =INDEX(NakshatraTbl,INT(G37*0.075)+1,1) -> Jyeshtha | F37: =INDEX(PanchangaYoga,INT((MOD(360+G37-PushyaDegree,360))*0.075)+1,2) -> Vriddhi | G37: =MOD(SunDeg+MoonDeg+PushyaDegree,360) -> 238.74848 | H37: =B37+D37/60 -> 28.748333 | I37: =INDEX(NakshatraTbl,INT(G37*0.075)+1,3) -> Merc | J37: Called "Yogi Point" by Sheshadri Iyer
A38: Ava Yoga/Yogi | B38: =FLOOR(MOD(G38,30),1) -> 5 | C38: =INDEX(RasiDeg,ROUNDUP(G38/30,0),1) -> Ge | D38: =ROUND((MOD(G38,30)-B38)*60,1) -> 24.9 | E38: =INDEX(NakshatraTbl,INT(G38*0.075)+1,1) -> Mrigashira | F38: =INDEX(PanchangaYoga,INT(14*StarDeg*0.075)+1,2) -> Vajra | G38: =MOD(YogiDeg+14*StarDeg,360) -> 65.415147 | H38: =B38+D38/60 -> 5.415 | I38: =INDEX(NakshatraTbl,INT(G38*0.075)+1,3) -> Mars
A39: Sun+Rahu | B39: =FLOOR(MOD(G39,30),1) -> 24 | C39: =INDEX(RasiDeg,ROUNDUP(G39/30,0),1) -> Ar | D39: =ROUND((MOD(G39,30)-B39)*60,1) -> 22 | E39: =INDEX(NakshatraTbl,INT(G39*0.075)+1,1) -> Bharani | G39: =MOD(G8+G15,360) -> 24.366442 | H39: =B39+D39/60 -> 24.366667 | I39: =INDEX(NakshatraTbl,INT(G39*0.075)+1,3) -> Venus
A40: Sun+Saturn | B40: =FLOOR(MOD(G40,30),1) -> 12 | C40: =INDEX(RasiDeg,ROUNDUP(G40/30,0),1) -> Le | D40: =ROUND((MOD(G40,30)-B40)*60,1) -> 17.1 | E40: =INDEX(NakshatraTbl,INT(G40*0.075)+1,1) -> Magha | G40: =MOD(G8+G14,360) -> 132.28441 | H40: =B40+D40/60 -> 12.285 | I40: =INDEX(NakshatraTbl,INT(G40*0.075)+1,3) -> Ketu
A41: Sun+Venus | B41: =FLOOR(MOD(G41,30),1) -> 23 | C41: =INDEX(RasiDeg,ROUNDUP(G41/30,0),1) -> Vi | D41: =ROUND((MOD(G41,30)-B41)*60,1) -> 56.4 | E41: =INDEX(NakshatraTbl,INT(G41*0.075)+1,1) -> Chitra | G41: =MOD(G8+G13,360) -> 173.93981 | H41: =B41+D41/60 -> 23.94 | I41: =INDEX(NakshatraTbl,INT(G41*0.075)+1,3) -> Mars | K41: =FIND(" - ",JHora!A32) -> #VALUE! | L41: =ISERR(K41) -> TRUE
...

Sheet Charts
A1: {={1,2,3}} -> 1 | B1: 2 | C1: 3
B2: * * * | C2: =J2 -> Moon/ Saturn/ | D2: =I2 | E2: =H2 | F2: * * * | H2: =IF(TRUNC(Basics!B67/30)=11,Basics!$A$67&"/ ","")&IF(TRUNC(Basics!B60/30)=11,Basics!$A$60&"/ ","")&IF(TRUNC(Basics!B58/30)=11,Basics!$A$58&"/ ","")&IF(TRUNC(Basics!B59/30)=11,Basics!$A$59&"/ ","")&IF(TRUNC(Basics!B66/30)=11,Basics!$A$66&"/ ","")&IF(TRUNC(Basics!B61/30)=11,Basics!$A$61&"/ ","")&IF(TRUNC(Basics!B65/30)=11,Basics!$A$65&"/ ","")&IF(TRUNC(Basics!B62/30)=11,Basics!$A$62&"/ ","")&IF(TRUNC(Basics!B63/30)=11,Basics!$A$63&"/ ","")&IF(TRUNC(Basics!B64/30)=11,Basics!$A$64&"/ ","") | I2: =IF(TRUNC(Basics!B67/30)=0,Basics!$A$67&"/ ","")&IF(TRUNC(Basics!B60/30)=0,Basics!$A$60&"/ ","")&IF(TRUNC(Basics!B58/30)=0,Basics!$A$58&"/ ","")&IF(TRUNC(Basics!B59/30)=0,Basics!$A$59&"/ ","")&IF(TRUNC(Basics!B66/30)=0,Basics!$A$66&"/ ","")&IF(TRUNC(Basics!B61/30)=0,Basics!$A$61&"/ ","")&IF(TRUNC(Basics!B65/30)=0,Basics!$A$65&"/ ","")&IF(TRUNC(Basics!B62/30)=0,Basics!$A$62&"/ ","")&IF(TRUNC(Basics!B63/30)=0,Basics!$A$63&"/ ","")&IF(TRUNC(Basics!B64/30)=0,Basics!$A$64&"/ ","") | J2: =IF(TRUNC(Basics!B67/30)=1,Basics!$A$67&"/ ","")&IF(TRUNC(Basics!B60/30)=1,Basics!$A$60&"/ ","")&IF(TRUNC(Basics!B58/30)=1,Basics!$A$58&"/ ","")&IF(TRUNC(Basics!B59/30)=1,Basics!$A$59&"/ ","")&IF(TRUNC(Basics!B66/30)=1,Basics!$A$66&"/ ","")&IF(TRUNC(Basics!B61/30)=1,Basics!$A$61&"/ ","")&IF(TRUNC(Basics!B65/30)=1,Basics!$A$65&"/ ","")&IF(TRUNC(Basics!B62/30)=1,Basics!$A$62&"/ ","")&IF(TRUNC(Basics!B63/30)=1,Basics!$A$63&"/ ","")&IF(TRUNC(Basics!B64/30)=1,Basics!$A$64&"/ ","") -> Moon/ Saturn/ | K2: =IF(TRUNC(Basics!B67/30)=2,Basics!$A$67&"/ ","")&IF(TRUNC(Basics!B60/30)=2,Basics!$A$60&"/ ","")&IF(TRUNC(Basics!B58/30)=2,Basics!$A$58&"/ ","")&IF(TRUNC(Basics!B59/30)=2,Basics!$A$59&"/ ","")&IF(TRUNC(Basics!B66/30)=2,Basics!$A$66&"/ ","")&IF(TRUNC(Basics!B61/30)=2,Basics!$A$61&"/ ","")&IF(TRUNC(Basics!B65/30)=2,Basics!$A$65&"/ ","")&IF(TRUNC(Basics!B62/30)=2,Basics!$A$62&"/ ","")&IF(TRUNC(Basics!B63/30)=2,Basics!$A$63&"/ ","")&IF(TRUNC(Basics!B64/30)=2,Basics!$A$64&"/ ","") -> Venus/
B3: =K2 -> Venus/ | C3: * * * | E3: * * * | F3: =H3 | H3: =IF(TRUNC(Basics!B67/30)=10,Basics!$A$67&"/ ","")&IF(TRUNC(Basics!B60/30)=10,Basics!$A$60&"/ ","")&IF(TRUNC(Basics!B58/30)=10,Basics!$A$58&"/ ","")&IF(TRUNC(Basics!B59/30)=10,Basics!$A$59&"/ ","")&IF(TRUNC(Basics!B66/30)=10,Basics!$A$66&"/ ","")&IF(TRUNC(Basics!B61/30)=10,Basics!$A$61&"/ ","")&IF(TRUNC(Basics!B65/30)=10,Basics!$A$65&"/ ","")&IF(TRUNC(Basics!B62/30)=10,Basics!$A$62&"/ ","")&IF(TRUNC(Basics!B63/30)=10,Basics!$A$63&"/ ","")&IF(TRUNC(Basics!B64/30)=10,Basics!$A$64&"/ ","") | I3: RASI CHART | K3: =IF(TRUNC(Basics!B67/30)=3,Basics!$A$67&"/ ","")&IF(TRUNC(Basics!B60/30)=3,Basics!$A$60&"/ ","")&IF(TRUNC(Basics!B58/30)=3,Basics!$A$58&"/ ","")&IF(TRUNC(Basics!B59/30)=3,Basics!$A$59&"/ ","")&IF(TRUNC(Basics!B66/30)=3,Basics!$A$66&"/ ","")&IF(TRUNC(Basics!B61/30)=3,Basics!$A$61&"/ ","")&IF(TRUNC(Basics!B65/30)=3,Basics!$A$65&"/ ","")&IF(TRUNC(Basics!B62/30)=3,Basics!$A$62&"/ ","")&IF(TRUNC(Basics!B63/30)=3,Basics!$A$63&"/ ","")&IF(TRUNC(Basics!B64/30)=3,Basics!$A$64&"/ ","") -> Ketu/ Sun/ Mercury/
B4: =K3 -> Ketu/ Sun/ Mercury/ | D4: Rashi | F4: =H4 -> Rahu/ Mars/ | H4: =IF(TRUNC(Basics!B67/30)=9,Basics!$A$67&"/ ","")&IF(TRUNC(Basics!B60/30)=9,Basics!$A$60&"/ ","")&IF(TRUNC(Basics!B58/30)=9,Basics!$A$58&"/ ","")&IF(TRUNC(Basics!B59/30)=9,Basics!$A$59&"/ ","")&IF(TRUNC(Basics!B66/30)=9,Basics!$A$66&"/ ","")&IF(TRUNC(Basics!B61/30)=9,Basics!$A$61&"/ ","")&IF(TRUNC(Basics!B65/30)=9,Basics!$A$65&"/ ","")&IF(TRUNC(Basics!B62/30)=9,Basics!$A$62&"/ ","")&IF(TRUNC(Basics!B63/30)=9,Basics!$A$63&"/ ","")&IF(TRUNC(Basics!B64/30)=9,Basics!$A$64&"/ ","") -> Rahu/ Mars/ | J4: D1 | K4: =IF(TRUNC(Basics!B67/30)=4,Basics!$A$67&"/ ","")&IF(TRUNC(Basics!B60/30)=4,Basics!$A$60&"/ ","")&IF(TRUNC(Basics!B58/30)=4,Basics!$A$58&"/ ","")&IF(TRUNC(Basics!B59/30)=4,Basics!$A$59&"/ ","")&IF(TRUNC(Basics!B66/30)=4,Basics!$A$66&"/ ","")&IF(TRUNC(Basics!B61/30)=4,Basics!$A$61&"/ ","")&IF(TRUNC(Basics!B65/30)=4,Basics!$A$65&"/ ","")&IF(TRUNC(Basics!B62/30)=4,Basics!$A$62&"/ ","")&IF(TRUNC(Basics!B63/30)=4,Basics!$A$63&"/ ","")&IF(TRUNC(Basics!B64/30)=4,Basics!$A$64&"/ ","") -> Asc/
B5: =K4 -> Asc/ | C5: * * * | D5: =J5 | E5: * * * | F5: =H5 | H5: =IF(TRUNC(Basics!B67/30)=8,Basics!$A$67&"/ ","")&IF(TRUNC(Basics!B60/30)=8,Basics!$A$60&"/ ","")&IF(TRUNC(Basics!B58/30)=8,Basics!$A$58&"/ ","")&IF(TRUNC(Basics!B59/30)=8,Basics!$A$59&"/ ","")&IF(TRUNC(Basics!B66/30)=8,Basics!$A$66&"/ ","")&IF(TRUNC(Basics!B61/30)=8,Basics!$A$61&"/ ","")&IF(TRUNC(Basics!B65/30)=8,Basics!$A$65&"/ ","")&IF(TRUNC(Basics!B62/30)=8,Basics!$A$62&"/ ","")&IF(TRUNC(Basics!B63/30)=8,Basics!$A$63&"/ ","")&IF(TRUNC(Basics!B64/30)=8,Basics!$A$64&"/ ","") | I5: =IF(TRUNC(Basics!B67/30)=7,Basics!$A$67&"/ ","")&IF(TRUNC(Basics!B60/30)=7,Basics!$A$60&"/ ","")&IF(TRUNC(Basics!B58/30)=7,Basics!$A$58&"/ ","")&IF(TRUNC(Basics!B59/30)=7,Basics!$A$59&"/ ","")&IF(TRUNC(Basics!B66/30)=7,Basics!$A$66&"/ ","")&IF(TRUNC(Basics!B61/30)=7,Basics!$A$61&"/ ","")&IF(TRUNC(Basics!B65/30)=7,Basics!$A$65&"/ ","")&IF(TRUNC(Basics!B62/30)=7,Basics!$A$62&"/ ","")&IF(TRUNC(Basics!B63/30)=7,Basics!$A$63&"/ ","")&IF(TRUNC(Basics!B64/30)=7,Basics!$A$64&"/ ","") -> Jupiter/ | J5: =IF(TRUNC(Basics!B67/30)=6,Basics!$A$67&"/ ","")&IF(TRUNC(Basics!B60/30)=6,Basics!$A$60&"/ ","")&IF(TRUNC(Basics!B58/30)=6,Basics!$A$58&"/ ","")&IF(TRUNC(Basics!B59/30)=6,Basics!$A$59&"/ ","")&IF(TRUNC(Basics!B66/30)=6,Basics!$A$66&"/ ","")&IF(TRUNC(Basics!B61/30)=6,Basics!$A$61&"/ ","")&IF(TRUNC(Basics!B65/30)=6,Basics!$A$65&"/ ","")&IF(TRUNC(Basics!B62/30)=6,Basics!$A$62&"/ ","")&IF(TRUNC(Basics!B63/30)=6,Basics!$A$63&"/ ","")&IF(TRUNC(Basics!B64/30)=6,Basics!$A$64&"/ ","") | K5: =IF(TRUNC(Basics!B67/30)=5,Basics!$A$67&"/ ","")&IF(TRUNC(Basics!B60/30)=5,Basics!$A$60&"/ ","")&IF(TRUNC(Basics!B58/30)=5,Basics!$A$58&"/ ","")&IF(TRUNC(Basics!B59/30)=5,Basics!$A$59&"/ ","")&IF(TRUNC(Basics!B66/30)=5,Basics!$A$66&"/ ","")&IF(TRUNC(Basics!B61/30)=5,Basics!$A$61&"/ ","")&IF(TRUNC(Basics!B65/30)=5,Basics!$A$65&"/ ","")&IF(TRUNC(Basics!B62/30)=5,Basics!$A$62&"/ ","")&IF(TRUNC(Basics!B63/30)=5,Basics!$A$63&"/ ","")&IF(TRUNC(Basics!B64/30)=5,Basics!$A$64&"/ ","")
B6: * * * | C6: =K5 | D6: =J5 | E6: =I5 -> Jupiter/ | F6: * * *

Sheet Sp.Nakshatra
B1: Special Nakshatras From | D1: =INT(MoonDeg*0.075)+1 -> 4 | H1: =IF(D1>21,D1-1,D1) -> 4
A2: Nakshatra Name | B2: Sanskrit | C2: Ref: | D2: Number | E2: 28 Nx | F2: Lords | G2: * | I2: 27 Nx | J2: Lords | K2: Navamsa House | L2: Pada
A3: Janma/Pritvi | B3: Janma | C3: 1 | D3: =MOD(C3+D$1+26,28)+1 -> 4 | E3: =INDEX(NaxNames28,D3) -> Rohini | F3: =INDEX(NakshatraTbl,D3,3) -> Moon | G3: * | H3: =MOD(C3+H$1+25,27)+1 -> 4 | I3: =VLOOKUP(H3,NakshatraInfo,2) -> Rohini | J3: =VLOOKUP(H3,NakshatraInfo,4) -> Moon
A4: Jaati | B4: जाति jāti | C4: 4 | D4: =MOD(C4+D$1+26,28)+1 -> 7 | E4: =INDEX(NaxNames28,D4) -> Punarvasu | F4: =INDEX(NakshatraTbl,D4,3) -> Jupiter | G4: * | H4: =MOD(C4+H$1+25,27)+1 -> 7 | I4: =VLOOKUP(H4,NakshatraInfo,2) -> Punarvasu | J4: =VLOOKUP(H4,NakshatraInfo,4) -> Jupiter
A5: Naidhana | B5: नैधन naidhana | C5: 7 | D5: =MOD(C5+D$1+26,28)+1 -> 10 | E5: =INDEX(NaxNames28,D5) -> Magha | F5: =INDEX(NakshatraTbl,D5,3) -> Ketu | G5: * | H5: =MOD(C5+H$1+25,27)+1 -> 10 | I5: =VLOOKUP(H5,NakshatraInfo,2) -> Magha | J5: =VLOOKUP(H5,NakshatraInfo,4) -> Ketu
A6: Mātṛi /King | B6: मतृ matṛ | C6: 8 | D6: =MOD(C6+D$1+26,28)+1 -> 11 | E6: =INDEX(NaxNames28,D6) -> P. Phalguni | F6: =INDEX(NakshatraTbl,D6,3) -> Venus | G6: * | H6: =MOD(C6+H$1+25,27)+1 -> 11 | I6: =VLOOKUP(H6,NakshatraInfo,2) -> Purva Phalguni | J6: =VLOOKUP(H6,NakshatraInfo,4) -> Venus
A7: Karma/Dvija/Dwijanma | B7: कर्म karma | C7: 10 | D7: =MOD(C7+D$1+26,28)+1 -> 13 | E7: =INDEX(NaxNames28,D7) -> Hasta | F7: =INDEX(NakshatraTbl,D7,3) -> Moon | G7: * | H7: =MOD(C7+H$1+25,27)+1 -> 13 | I7: =VLOOKUP(H7,NakshatraInfo,2) -> Hasta | J7: =VLOOKUP(H7,NakshatraInfo,4) -> Moon | K7: 10
A8: Income??/Needs Chastity | C8: 11 | D8: =MOD(C8+D$1+26,28)+1 -> 14 | E8: =INDEX(NaxNames28,D8) -> Chitra | F8: =INDEX(NakshatraTbl,D8,3) -> Mars | G8: * | H8: =MOD(C8+H$1+25,27)+1 -> 14 | I8: =VLOOKUP(H8,NakshatraInfo,2) -> Chitra | J8: =VLOOKUP(H8,NakshatraInfo,4) -> Mars
A9: Desha | B9: देश deśa | C9: 12 | D9: =MOD(C9+D$1+26,28)+1 -> 15 | E9: =INDEX(NaxNames28,D9) -> Swati | F9: =INDEX(NakshatraTbl,D9,3) -> Rahu | G9: * | H9: - | I9: - | J9: - | K9: 12
A10: Assistant/Raajya/Destiny | B10: राज्य rājya | C10: 13 | D10: =MOD(C10+D$1+26,28)+1 -> 16 | E10: =INDEX(NaxNames28,D10) -> Vishaka | F10: =INDEX(NakshatraTbl,D10,3) -> Jupiter | G10: * | H10: =MOD(C10+H$1+25,27)+1 -> 16 | I10: =VLOOKUP(H10,NakshatraInfo,2) -> Vishakha | J10: =VLOOKUP(H10,NakshatraInfo,4) -> Jupiter | K10: 1
A11: DNA?? | C11: 14 | D11: =MOD(C11+D$1+26,28)+1 -> 17 | E11: =INDEX(NaxNames28,D11) -> Anuradha | F11: =INDEX(NakshatraTbl,D11,3) -> Sat | G11: * | H11: =MOD(C11+H$1+25,27)+1 -> 17 | I11: =VLOOKUP(H11,NakshatraInfo,2) -> Anuradha | J11: =VLOOKUP(H11,NakshatraInfo,4) -> Sat
A12: New Start ?? Self | C12: 15 | D12: =MOD(C12+D$1+26,28)+1 -> 18 | E12: =INDEX(NaxNames28,D12) -> Jyeshta | F12: =INDEX(NakshatraTbl,D12,3) -> Merc | G12: * | H12: =MOD(C12+H$1+25,27)+1 -> 18
A13: Sanghaatika/Kundalini | B13: सङ्गटिक saṅgāṭika | C13: 16 | D13: =MOD(C13+D$1+26,28)+1 -> 19 | E13: =INDEX(NaxNames28,D13) -> Moola | F13: =INDEX(NakshatraTbl,D13,3) -> Ketu | G13: * | H13: =MOD(C13+H$1+25,27)+1 -> 19 | I13: =VLOOKUP(H13,NakshatraInfo,2) -> Mula | J13: =VLOOKUP(H13,NakshatraInfo,4) -> Ketu | K13: 4
A14: Chandra Ashtama (Follower) | B14: Ashtama Nakshatra | C14: 17 | D14: - | E14: - | F14: - | G14: * | H14: =MOD(C14+H$1+25,27)+1 -> 20 | I14: =VLOOKUP(H14,NakshatraInfo,2) -> Purva Ashadha | J14: =VLOOKUP(H14,NakshatraInfo,4) -> Venus
A15: Samudaayika | B15: समुदायिक samudāyika | C15: 18 | D15: =MOD(C15+D$1+26,28)+1 -> 21 | E15: =INDEX(NaxNames28,D15) -> U. Ashada | F15: =INDEX(NakshatraTbl,D15,3) -> Sun | G15: * | H15: =MOD(C15+H$1+25,27)+1 -> 21 | I15: =VLOOKUP(H15,NakshatraInfo,2) -> Uttara Ashadha | J15: =VLOOKUP(H15,NakshatraInfo,4) -> Sun | K15: 6
A16: Aadhana/Father | B16: आधन ādhana | C16: 19 | D16: =MOD(C16+D$1+26,28)+1 -> 22 | E16: =INDEX(NaxNames28,D16) -> Abhjit | F16: =INDEX(NakshatraTbl,D16,3) -> Sun | G16: * | H16: =MOD(C16+H$1+25,27)+1 -> 22 | I16: =VLOOKUP(H16,NakshatraInfo,2) -> Shravan | J16: =VLOOKUP(H16,NakshatraInfo,4) -> Moon | K16: 7
A17: How you write Like Ganesha Guru Word/Recollect | C17: 20 | D17: =MOD(C17+D$1+26,28)+1 -> 23 | E17: =INDEX(NaxNames28,D17) -> Sravana | F17: =INDEX(NakshatraTbl,D17,3) -> Moon | G17: * | H17: =MOD(C17+H$1+25,27)+1 -> 23 | I17: =VLOOKUP(H17,NakshatraInfo,2) -> Dhanistha | J17: =VLOOKUP(H17,NakshatraInfo,4) -> Mars
A18: Takes to Spirituality/Transformation?? | C18: 21 | D18: =MOD(C18+D$1+26,28)+1 -> 24 | E18: =INDEX(NaxNames28,D18) -> Dhanishta | F18: =INDEX(NakshatraTbl,D18,3) -> Mars | G18: * | H18: =MOD(C18+H$1+25,27)+1 -> 24 | I18: =VLOOKUP(H18,NakshatraInfo,2) -> Satabishak | J18: =VLOOKUP(H18,NakshatraInfo,4) -> Rahu
A19: Vainashika | B19: वैनशिक vainaśika | C19: 22 | D19: =MOD(C19+D$1+26,28)+1 -> 25 | E19: =INDEX(NaxNames28,D19) -> Shatabhishaj | F19: =INDEX(NakshatraTbl,D19,3) -> Rahu | G19: * | H19: =MOD(C19+H$1+25,27)+1 -> 25 | I19: =VLOOKUP(H19,NakshatraInfo,2) -> Purva Bhadrapad | J19: =VLOOKUP(H19,NakshatraInfo,4) -> Jupiter | K19: 10
A20: Initiations | C20: 23 | D20: =MOD(C20+D$1+26,28)+1 -> 26 | E20: =INDEX(NaxNames28,D20) -> P. Bhadra | F20: =INDEX(NakshatraTbl,D20,3) -> Jupiter | H20: =MOD(C20+H$1+25,27)+1 -> 26
A21: Iccha Mṛityu/Sati | C21: 24 | D21: =MOD(C21+D$1+26,28)+1 -> 27 | E21: =INDEX(NaxNames28,D21) -> U. Bhadra | F21: =INDEX(NakshatraTbl,D21,3) -> Sat | H21: =MOD(C21+H$1+25,27)+1 -> 27
A22: Maanasa/Jaati(?)/Vayu | B22: मानस mānasa | C22: 25 | D22: =MOD(C22+D$1+26,28)+1 -> 28 | E22: =INDEX(NaxNames28,D22) -> Revati | F22: =INDEX(NakshatraTbl,D22,3) -> Merc | G22: * | H22: =MOD(C22+H$1+25,27)+1 -> 1 | I22: =VLOOKUP(H22,NakshatraInfo,2) -> Ashvini | J22: =VLOOKUP(H22,NakshatraInfo,4) -> Ketu | K22: 1
A23: Brahma(?)/Desha(?)/Agni | C23: 26 | D23: =MOD(C23+D$1+26,28)+1 -> 1 | E23: =INDEX(NaxNames28,D23) -> Ashwini | F23: =INDEX(NakshatraTbl,D23,3) -> Ketu | G23: * | H23: - | I23: - | J23: -
A24: Vishnu/Aakaasha | C24: 27 | D24: =MOD(C24+D$1+26,28)+1 -> 2 | E24: =INDEX(NaxNames28,D24) -> Bharani | F24: =INDEX(NakshatraTbl,D24,3) -> Venus | G24: * | H24: =MOD(C24+H$1+25,27)+1 -> 3 | I24: =VLOOKUP(H24,NakshatraInfo,2) -> Kritika | J24: =VLOOKUP(H24,NakshatraInfo,4) -> Sun | K24: 3
A25: Abhisheka/Jala | B25: अभिशेक abhiśeka | C25: 28 | D25: =MOD(C25+D$1+26,28)+1 -> 3 | E25: =INDEX(NaxNames28,D25) -> Krittika | F25: =INDEX(NakshatraTbl,D25,3) -> Sun | G25: * | H25: - | I25: - | J25: - | K25: 3
A27: Special Nakshatras From Sun | B27: =INT(SunDeg*0.075)+1 -> 7 | D27: =INDEX(NaxNames28,B27) -> Punarvasu
A28: Role | B28: Meaning | C28: Ref: | D28: Nax # | F28: 27 Nx | G28: Lords | I28: 28 Nx
A29: Vidyunmukha | B29: mouth of lightning | C29: 5 | D29: =MOD(C29+B$27+25,27)+1 -> 11 | E29: =INDEX(NakshatraTbl,D29,1) -> Purva Phalguni | G29: =INDEX(NakshatraTbl,D29,3) -> Venus | H29: =MOD(C29+B$27+26,28)+1 -> 11 | I29: =INDEX(NaxNames28,H29) -> P. Phalguni
A30: Shula | B30: sharp and piercing | C30: 8 | D30: =MOD(C30+B$27+25,27)+1 -> 14 | E30: =INDEX(NakshatraTbl,D30,1) -> Chitra | G30: =INDEX(NakshatraTbl,D30,3) -> Mars | H30: =MOD(C30+B$27+26,28)+1 -> 14 | I30: =INDEX(NaxNames28,H30) -> Chitra
A31: Sannipata | B31: trouble creator like Saturn | C31: 14 | D31: =MOD(C31+B$27+25,27)+1 -> 20 | E31: =INDEX(NakshatraTbl,D31,1) -> Purva Ashadha | G31: =INDEX(NakshatraTbl,D31,3) -> Venus | H31: =MOD(C31+B$27+26,28)+1 -> 20 | I31: =INDEX(NaxNames28,H31) -> P. Ashada
A32: Ketu | B32: unpredictable | C32: 18 | D32: =MOD(C32+B$27+25,27)+1 -> 24 | E32: =INDEX(NakshatraTbl,D32,1) -> Dhanistha | G32: =INDEX(NakshatraTbl,D32,3) -> Mars | H32: =MOD(C32+B$27+26,28)+1 -> 24 | I32: =INDEX(NaxNames28,H32) -> Dhanishta
A33: Ulka | B33: fireball | C33: 21 | D33: =MOD(C33+B$27+25,27)+1 -> 27 | E33: =INDEX(NakshatraTbl,D33,1) -> Uttara Bhadrapad | G33: =INDEX(NakshatraTbl,D33,3) -> Sat | H33: =MOD(C33+B$27+26,28)+1 -> 27 | I33: =INDEX(NaxNames28,H33) -> U. Bhadra
A34: Kampa | B34: shiver | C34: 22 | D34: =MOD(C34+B$27+25,27)+1 -> 1 | E34: =INDEX(NakshatraTbl,D34,1) -> Ashvini | G34: =INDEX(NakshatraTbl,D34,3) -> Ketu | H34: =MOD(C34+B$27+26,28)+1 -> 28 | I34: =INDEX(NaxNames28,H34) -> Revati
A35: Vajraka | B35: lighning | C35: 23 | D35: =MOD(C35+B$27+25,27)+1 -> 2 | E35: =INDEX(NakshatraTbl,D35,1) -> Bharani | G35: =INDEX(NakshatraTbl,D35,3) -> Venus | H35: =MOD(C35+B$27+26,28)+1 -> 1 | I35: =INDEX(NaxNames28,H35) -> Ashwini
A36: Nirghata | B36: deadly | C36: 24 | D36: =MOD(C36+B$27+25,27)+1 -> 3 | E36: =INDEX(NakshatraTbl,D36,1) -> Kritika | G36: =INDEX(NakshatraTbl,D36,3) -> Sun | H36: =MOD(C36+B$27+26,28)+1 -> 2 | I36: =INDEX(NaxNames28,H36) -> Bharani
A39: Navatara | B39: Kaaraka | C39: # | D39: Ruler | E39: Deha | F39: Navatara 1 | G39: Use 1st Level | H39: Manasa | I39: Navatara 2 | J39: Use 2 | K39: Atma | L39: Navatara 3 | M39: Use 3 | N39: Ruler_ | O39: #2
A40: Janma | B40: Moon | C40: 1 | D40: =VLOOKUP(E40,NakshatraInfo,4) -> Moon | E40: =D1 -> 4 | F40: =VLOOKUP(E40,NakshatraInfo,2) -> Rohini | G40: Janma | H40: =MOD(E48,27)+1 -> 13 | I40: =VLOOKUP(H40,NakshatraInfo,2) -> Hasta | J40: Karma | K40: =MOD(H48,27)+1 -> 22 | L40: =VLOOKUP(K40,NakshatraInfo,2) -> Shravan | M40: Pita/Guru | N40: =VLOOKUP(K40,NakshatraInfo,4) -> Moon | O40: 1
A41: Sampat | B41: Mars | C41: 2 | D41: =VLOOKUP(E41,NakshatraInfo,4) -> Mars | E41: =MOD(E40,27)+1 -> 5 | F41: =VLOOKUP(E41,NakshatraInfo,2) -> Mrigashira | G41: Dhana-Dhaanya | H41: =MOD(H40,27)+1 -> 14 | I41: =VLOOKUP(H41,NakshatraInfo,2) -> Chitra | J41: Vivaaha | K41: =MOD(K40,27)+1 -> 23 | L41: =VLOOKUP(K41,NakshatraInfo,2) -> Dhanistha | M41: Aaraadhana/Bhaagya | N41: =VLOOKUP(K41,NakshatraInfo,4) -> Mars | O41: 2
A42: Vipat | B42: Rahu | C42: 3 | D42: =VLOOKUP(E42,NakshatraInfo,4) -> Rahu | E42: =MOD(E41,27)+1 -> 6 | F42: =VLOOKUP(E42,NakshatraInfo,2) -> Ardra | G42: Kashta-Durbhaagya | H42: =MOD(H41,27)+1 -> 15 | I42: =VLOOKUP(H42,NakshatraInfo,2) -> Swati | J42: Durbalata | K42: =MOD(K41,27)+1 -> 24 | L42: =VLOOKUP(K42,NakshatraInfo,2) -> Satabishak | M42: Dishaa/Patha | N42: =VLOOKUP(K42,NakshatraInfo,4) -> Rahu | O42: 3
A43: Kshema/Jaati | B43: Jupiter | C43: 4 | D43: =VLOOKUP(E43,NakshatraInfo,4) -> Jupiter | E43: =MOD(E42,27)+1 -> 7 | F43: =VLOOKUP(E43,NakshatraInfo,2) -> Punarvasu | G43: Aashraya-Raksha | H43: =MOD(H42,27)+1 -> 16 | I43: =VLOOKUP(H43,NakshatraInfo,2) -> Vishakha | J43: Suraksha | K43: =MOD(K42,27)+1 -> 25 | L43: =VLOOKUP(K43,NakshatraInfo,2) -> Purva Bhadrapad | M43: Devaalaya/Garbha Griha | N43: =VLOOKUP(K43,NakshatraInfo,4) -> Jupiter | O43: 4
...

Sheet Ayush
B1: Degree | E1: Pinda (sun) | H1: Nisarga(Moon) | K1: Amsha (Lagna Lord) | M1: Samudaya Ashtakavarga (Saturn) | N1: Rashmi (Mercury) | Q1: Kaalachakra(Venus) | R1: BhinnaAshtakvarga (Mars) | S1: Nakshatraja (Jupiter)
A2: Graha | B2: Jataka | C2: Debility | D2: Distance | E2: Maana | F2: Correction | G2: Age-P | H2: Maana2 | I2: Correction3 | J2: Age-N | K2: D9 | L2: Correction5 | M2: Age-A | N2: MaanaR | O2: Age-R | P2: Factor | Q2: Age-K | R2: Age-B | S2: Age-Nx
A3: Sun | B3: =INDIRECT(A3) -> 92.399203 | C3: =SunDeb -> 190 | D3: =(1-COS((360+B3-C3)/180*PI()))/2 -> 0.56613509 | E3: 19 | G3: =(1-COS((360+B3-C3)/180*PI()))/2*E3 -> 10.756567 | H3: 1 | J3: =(1-COS((360+B3-C3)/180*PI()))/2*H3 -> 0.56613509 | K3: =MOD(B3/3.333,12) -> 3.7225331 | M3: =Ashtakavarga!P30 -> 8.0383294 | N3: 10 | O3: =N3*$D3*Table19[[#This Row],[Factor]] -> 5.6613509 | P3: 1
A4: Moon | B4: =INDIRECT(A4) -> 53.015944 | C4: =MoonDeb -> 213 | D4: =(1-COS((360+B4-C4)/180*PI()))/2 -> 0.9697987 | E4: 25 | G4: =(1-COS((360+B4-C4)/180*PI()))/2*E4 -> 24.244968 | H4: 2 | J4: =(1-COS((360+B4-C4)/180*PI()))/2*H4 -> 1.9395974 | K4: =MOD(B4/3.333,12) -> 3.906374 | M4: =Ashtakavarga!P31 -> 20.049281 | N4: 9 | O4: =N4*$D4*Table19[[#This Row],[Factor]] -> 26.184565 | P4: 3
A5: Mars | B5: =INDIRECT(A5) -> 298.10866 | C5: =MarsDeb -> 118 | D5: =(1-COS((360+B5-C5)/180*PI()))/2 -> 0.9999991 | E5: 15 | G5: =(1-COS((360+B5-C5)/180*PI()))/2*E5 -> 14.999987 | H5: 9 | J5: =(1-COS((360+B5-C5)/180*PI()))/2*H5 -> 8.9999919 | K5: =MOD(B5/3.333,12) -> 5.4415433 | M5: =Ashtakavarga!P32 -> 20.043805 | N5: 5 | O5: =N5*$D5*Table19[[#This Row],[Factor]] -> 14.999987 | P5: 3
A6: Mercury | B6: =INDIRECT(A6) -> 117.12979 | C6: =MercDeb -> 345 | D6: =(1-COS((360+B6-C6)/180*PI()))/2 -> 0.83540613 | E6: 12 | G6: =(1-COS((360+B6-C6)/180*PI()))/2*E6 -> 10.024874 | H6: 20 | J6: =(1-COS((360+B6-C6)/180*PI()))/2*H6 -> 16.708123 | K6: =MOD(B6/3.333,12) -> 11.14245 | M6: =Ashtakavarga!P33 -> 14.124571 | N6: 5 | O6: =N6*$D6*Table19[[#This Row],[Factor]] -> 4.1770306 | P6: 1
A7: Jupiter | B7: =INDIRECT(A7) -> 213.19717 | C7: =JupDeb -> 275 | D7: =(1-COS((360+B7-C7)/180*PI()))/2 -> 0.26374634 | E7: 15 | G7: =(1-COS((360+B7-C7)/180*PI()))/2*E7 -> 3.9561952 | H7: 18 | J7: =(1-COS((360+B7-C7)/180*PI()))/2*H7 -> 4.7474342 | K7: =MOD(B7/3.333,12) -> 3.9655491 | M7: =Ashtakavarga!P34 -> 4.0971924 | N7: 7 | O7: =N7*$D7*Table19[[#This Row],[Factor]] -> 2.4554785 | P7: 1.33
